Workbook

Sheet README
A1: Foodle - curated content repository (v2)
A2: Prepared | B2: 16 October 2026
A3: Built from | B3: Foodle_Starter_Repository.xlsx (v1, 15 October 2026, 1,158 dishes and drinks)
A4: Status | B4: Draft. Rows still need an editorial fact check before launch. Clues and hints marked as authored in v2 were written for this version.
A6: What changed and why
A7: 1. Smaller, better-known pool | B7: Every dish and drink was scored 0-10 (see Scoring). Items below 6.5 were removed: niche items, near-duplicates and products that can't be clued well. 747 of 1,158 items stay (65%). Removed items and the reason for each are on the Removed sheet.
A8: 2. Clues that say more | B8: Basic pantry ingredients (salt, oil, ghee, onion, garlic and so on) are no longer clues. Each item now has six clues running from least to most telling, mixing specific ingredients with technique, serving and occasion details, plus one final hint sentence.
A9: 3. Pantry note for players | B9: Basic pantry isn't shown as a clue: salt, pepper, water, ice, sugar, cooking oil, ghee, flour, onion, garlic, ginger, green or red chilli, turmeric, cumin, coriander, garam masala, yeast and baking soda. Clues are the ingredients and details that make a dish what it is.
A10: Target difficulty | B10: Pick items most players recognise (aim: 60-80% of players win a daily puzzle) and give clues that let most players get there by the last clue or the final hint (aim: 75-90%).
A12: Sheets
A13: Scoring | B13: The scoring method. Weights and the cut-off are yellow input cells: change them and the Status column on All Items updates.
A14: All Items | B14: All 1,158 source items with their score, Keep/Remove status and the reason. Recognition, near-duplicate and single-ingredient columns are editorial inputs (yellow).
A15: Dishes / Drinks | B15: The kept items with their new clues (Clue 1-6), final hint, ingredient clues and mode flags. Score is looked up live from All Items.
A16: Removed | B16: Items cut from the pool, with score and reason. They can come back by raising their recognition or lowering the cut-off.
A17: Pantry | B17: The pantry list (always hidden) and the common list (used only when an item has few other clues).
A18: Summary | B18: Before/after counts by region, course, drink type, Indian state and game mode, all as live formulas.
A19: Ingredients | B19: Ingredients still used as clues, with live usage counts across the new clue columns.
A20: Cuisines / India States / Countries | B20: Reference sheets; item counts are live formulas over Dishes and Drinks.
A21: Daily Schedule (sample) | B21: A fresh 90-day sample drawn from the curated pool with the same rules as v1.
A23: How a clue row works now
A24: Clue 1 ... Clue 6 | B24: Reveal order: least telling first. Clue 1 is never a pantry staple. Clues that name part of the answer (giveaways) are always last.
A25: Final hint | B25: One sentence describing the dish without naming it. Shown after the last clue, so players who are still stuck get a fair last chance.
A26: Rebuild changes after editing | B26: Changing weights updates the Status column here. To move items between Dishes/Drinks and Removed, run packages/content/curation/build_workbook.py, which applies the same rules.
A28: Colour key
A29: Yellow cells | B29: Editorial inputs and scoring weights you can change.
A30: Blue text | B30: Hard-coded editorial values (recognition scores, weights).
A31: Green text | B31: Values looked up from another sheet.
A32: Black text | B32: Formulas or source data.
A34: Sources and licences
A35: Dish and drink content | B35: Compiled from general knowledge for the v1 draft; v2 clues and hints authored for Foodle. Check against a reference (Wikipedia/Wikidata, IBA for cocktails) before launch.
A36: Countries sheet | B36: mledoze/countries (github.com/mledoze/countries), ODbL 1.0: attribution required, share-alike applies.
A37: Images | B37: Image URL columns hold Wikimedia Commons candidates found by script (accepted licence, long edge at least 2,400 px). Status 'Candidate' means not yet reviewed by a person.

Sheet Summary
A1: Before and after
A2: v1 counts are fixed values from the source workbook. v2 counts are live formulas.
A4: Totals
A5: Items | B5: v1 (source) | C5: v2 (kept) | D5: Share kept
A6: Dishes | B6: 911 | C6: =COUNTA(Dishes!A:A)-1 -> 609 | D6: =IF(B6=0,0,C6/B6) -> 0.66849616
A7: Drinks | B7: 247 | C7: =COUNTA(Drinks!A:A)-1 -> 138 | D7: =IF(B7=0,0,C7/B7) -> 0.55870445
A8: All items | B8: 1158 | C8: =C6+C7 -> 747 | D8: =IF(B8=0,0,C8/B8) -> 0.64507772
A10: Dishes by continent
A11: Continent | B11: v1 (source) | C11: v2 (kept) | D11: Share kept
A12: Asia | B12: 590 | C12: =COUNTIF(Dishes!F:F,"Asia") -> 410 | D12: =IF(B12=0,0,C12/B12) -> 0.69491525
A13: Europe | B13: 186 | C13: =COUNTIF(Dishes!F:F,"Europe") -> 119 | D13: =IF(B13=0,0,C13/B13) -> 0.63978495
A14: Americas | B14: 86 | C14: =COUNTIF(Dishes!F:F,"Americas") -> 60 | D14: =IF(B14=0,0,C14/B14) -> 0.69767442
A15: Africa | B15: 39 | C15: =COUNTIF(Dishes!F:F,"Africa") -> 16 | D15: =IF(B15=0,0,C15/B15) -> 0.41025641
A16: Oceania | B16: 10 | C16: =COUNTIF(Dishes!F:F,"Oceania") -> 4 | D16: =IF(B16=0,0,C16/B16) -> 0.4
A17: of which India | B17: 363 | C17: =COUNTIF(Dishes!D:D,"India") -> 250 | D17: =IF(B17=0,0,C17/B17) -> 0.68870523
A19: Dishes by course
A20: Course | B20: v1 (source) | C20: v2 (kept) | D20: Share kept
A21: Main | B21: 334 | C21: =COUNTIF(Dishes!H:H,"Main") -> 221 | D21: =IF(B21=0,0,C21/B21) -> 0.66167665
A22: Snack | B22: 118 | C22: =COUNTIF(Dishes!H:H,"Snack") -> 73 | D22: =IF(B22=0,0,C22/B22) -> 0.61864407
A23: Dessert | B23: 87 | C23: =COUNTIF(Dishes!H:H,"Dessert") -> 63 | D23: =IF(B23=0,0,C23/B23) -> 0.72413793
A24: Street | B24: 67 | C24: =COUNTIF(Dishes!H:H,"Street") -> 46 | D24: =IF(B24=0,0,C24/B24) -> 0.68656716
A25: Breakfast | B25: 59 | C25: =COUNTIF(Dishes!H:H,"Breakfast") -> 48 | D25: =IF(B25=0,0,C25/B25) -> 0.81355932
A26: Soup | B26: 53 | C26: =COUNTIF(Dishes!H:H,"Soup") -> 34 | D26: =IF(B26=0,0,C26/B26) -> 0.64150943
A27: Sweet | B27: 51 | C27: =COUNTIF(Dishes!H:H,"Sweet") -> 32 | D27: =IF(B27=0,0,C27/B27) -> 0.62745098
A28: Rice | B28: 51 | C28: =COUNTIF(Dishes!H:H,"Rice") -> 39 | D28: =IF(B28=0,0,C28/B28) -> 0.76470588
A29: Side | B29: 38 | C29: =COUNTIF(Dishes!H:H,"Side") -> 17 | D29: =IF(B29=0,0,C29/B29) -> 0.44736842
A30: Bread | B30: 25 | C30: =COUNTIF(Dishes!H:H,"Bread") -> 14 | D30: =IF(B30=0,0,C30/B30) -> 0.56
A31: Condiment | B31: 14 | C31: =COUNTIF(Dishes!H:H,"Condiment") -> 12 | D31: =IF(B31=0,0,C31/B31) -> 0.85714286
A32: Salad | B32: 14 | C32: =COUNTIF(Dishes!H:H,"Salad") -> 10 | D32: =IF(B32=0,0,C32/B32) -> 0.71428571
A34: Drinks by type
A35: Type | B35: v1 (source) | C35: v2 (kept) | D35: Share kept
A36: Cocktail | B36: 79 | C36: =COUNTIF(Drinks!H:H,"Cocktail") -> 44 | D36: =IF(B36=0,0,C36/B36) -> 0.55696203
A37: Cold | B37: 59 | C37: =COUNTIF(Drinks!H:H,"Cold") -> 33 | D37: =IF(B37=0,0,C37/B37) -> 0.55932203
A38: Hot | B38: 40 | C38: =COUNTIF(Drinks!H:H,"Hot") -> 28 | D38: =IF(B38=0,0,C38/B38) -> 0.7
A39: Spirit | B39: 27 | C39: =COUNTIF(Drinks!H:H,"Spirit") -> 18 | D39: =IF(B39=0,0,C39/B39) -> 0.66666667
A40: Fermented | B40: 19 | C40: =COUNTIF(Drinks!H:H,"Fermented") -> 7 | D40: =IF(B40=0,0,C40/B40) -> 0.36842105
A41: Beer | B41: 8 | C41: =COUNTIF(Drinks!H:H,"Beer") -> 1 | D41: =IF(B41=0,0,C41/B41) -> 0.125
A42: Wine | B42: 7 | C42: =COUNTIF(Drinks!H:H,"Wine") -> 4 | D42: =IF(B42=0,0,C42/B42) -> 0.57142857
A43: Mocktail | B43: 7 | C43: =COUNTIF(Drinks!H:H,"Mocktail") -> 2 | D43: =IF(B43=0,0,C43/B43) -> 0.28571429
A44: Liqueur | B44: 1 | C44: =COUNTIF(Drinks!H:H,"Liqueur") -> 1 | D44: =IF(B44=0,0,C44/B44) -> 1
...

Sheet Scoring
B1: Scoring method
B2: Score out of 10 = recognition + distinctiveness + fit + clue strength. Items at or above the cut-off are kept.
B4: Component | C4: Weight | D4: Max points | E4: How it is scored
B5: Recognition (1-5) | C5: 1.3 | D5: =5*C5 -> 6.5 | E5: Editorial score: how widely known the item is to the players of its edition (Global players for non-Indian items, Indian players for Indian items). 5 household name, 4 widely known, 3 known to food-curious players, 2 niche, 1 obscure. Points = score x weight.
B6: Distinctiveness | C6: 2 | D6: =C6 -> 2 | E6: Full points unless the item is a near-duplicate of a better-known item (biryani variants, a second version of the same dumpling, a virgin version of a cocktail). Duplicates were flagged by hand and by checking 60%+ clue overlap within the same country.
B7: Fit for clue play | C7: 0.5 | D7: =C7 -> 0.5 | E7: Full points for dishes and mixed drinks. Zero for single-ingredient products (straight spirits, wines, beers, plain teas), which are hard to clue.
B8: Clue strength | C8: 1 | D8: =C8 -> 1 | E8: From the source data, how many telling clues remain once the pantry is removed: 5+ = 1, 4 = 0.75, 3 = 0.5, 2 = 0.25, fewer = 0. Points = that fraction x weight.
B9: Maximum score | D9: =SUM(D5:D8) -> 10
B10: Keep cut-off (score at or above) | C10: 6.5 | E10: Chosen so that 60-70% of items stay, as briefed. 6.5 keeps every recognisable, distinct item and drops niche ones (recognition 2 can reach at most 6.3).
B12: Result (live)
B13: Items scored | C13: =COUNTA('All Items'!A:A)-1 -> 1158
B14: Kept | C14: =COUNTIF('All Items'!R:R,"Keep") -> 747
B15: Removed | C15: =COUNTIF('All Items'!R:R,"Remove") -> 411
B16: Share kept | C16: =IF(C13=0,0,C14/C13) -> 0.64507772
B17: Dishes kept | C17: =COUNTIFS('All Items'!C:C,"Dish",'All Items'!R:R,"Keep") -> 609
B18: Drinks kept | C18: =COUNTIFS('All Items'!C:C,"Drink",'All Items'!R:R,"Keep") -> 138
B19: Average score of kept items | C19: =IFERROR(AVERAGEIF('All Items'!R:R,"Keep",'All Items'!Q:Q),0) -> 7.9109103
B21: Recognition scale
B22: 5 | E22: Household name for this audience (Butter Chicken, Sushi, Mojito)
B23: 4 | E23: Widely known (Rogan Josh, Bibimbap, Negroni)
B24: 3 | E24: Known to food-curious players (Shorshe Ilish, Khao Soi, Pisco Sour)
B25: 2 | E25: Niche (Chicken Changezi, Ma La Xiang Guo, Aviation)
B26: 1 | E26: Obscure
B28: Defaults: recognition starts from the source fame tier (fame 1 = 4, fame 2 = 3, fame 3 = 2) and was then set item by item; 230 items were moved up or down by hand.

Sheet Dishes
A1: ID | B1: Dish | C1: Also known as | D1: Country | E1: State / region | F1: Continent | G1: Subregion | H1: Course | I1: Diet | J1: Fame (1-3) | K1: Recognition (1-5) | L1: Score | M1: Clue 1 | N1: Clue 2 | O1: Clue 3 | P1: Clue 4 | Q1: Clue 5 | R1: Clue 6 | S1: Final hint | T1: Ingredient clues | U1: Giveaway clues (shown last) | V1: Clue count | W1: Global mode | X1: India mode | Y1: Country mode | Z1: Origin note | AA1: Image search (Wikimedia) | AB1: Image URL | AC1: Image licence | AD1: Image credit | AE1: Image status | AF1: Status
A2: D0001 | B2: Butter Chicken | C2: Murgh Makhani | D2: India | E2: Delhi | F2: Asia | G2: Southern Asia | H2: Main | I2: Non-veg | J2: 1 | K2: 5 | L2: =INDEX('All Items'!$Q:$Q,MATCH($A2,'All Items'!$A:$A,0)) -> 10 | M2: kasuri methi | N2: smoky tandoor-grilled pieces | O2: silky orange gravy | P2: served with naan | Q2: chicken | R2: butter | S2: Delhi's creamy, mildly spiced tomato curry with tandoori chicken, born at Moti Mahal | T2: kasuri methi; chicken; butter | U2: chicken; butter | V2: =COUNTA(M2:R2) -> 6 | W2: Yes | X2: Yes | Y2: Yes | AA2: https://commons.wikimedia.org/w/index.php?search=Butter+Chicken+food&title=Special:MediaSearch&type=image | AB2: https://thumb.wikimedia.org/wikipedia/commons/thumb/4/41/Butter_Chicken_%26_Butter_Naan_-_Home_-_Chandigarh_-_India_-_0006.jpg/1280px-Butter_Chicken_%26_Butter_Naan_-_Home_-_Chandigarh_-_India_-_0006.jpg | AC2: CC BY-SA 4.0 | AD2: Yuvraj Singh 97 | AE2: Candidate - review | AF2: Draft v2 - editorial check
A3: D0002 | B3: Chole Bhature | D3: India | E3: Punjab | F3: Asia | G3: Southern Asia | H3: Main | I3: Veg | J3: 1 | K3: 5 | L3: =INDEX('All Items'!$Q:$Q,MATCH($A3,'All Items'!$A:$A,0)) -> 9.75 | M3: chana masala | N3: chickpeas | O3: bhatura dough | P3: deep-fried puffed bread | Q3: spicy chickpea curry | R3: pickled onions on the side | S3: Punjab's big weekend plate: fluffy fried bread with spicy chickpea curry | T3: chana masala; chickpeas; bhatura dough | V3: =COUNTA(M3:R3) -> 6 | W3: Yes | X3: Yes | Y3: Yes | AA3: https://commons.wikimedia.org/w/index.php?search=Chole+Bhature+food&title=Special:MediaSearch&type=image | AE3: Needed | AF3: Draft v2 - editorial check
A4: D0003 | B4: Sarson da Saag | D4: India | E4: Punjab | F4: Asia | G4: Southern Asia | H4: Main | I4: Veg | J4: 1 | K4: 4 | L4: =INDEX('All Items'!$Q:$Q,MATCH($A4,'All Items'!$A:$A,0)) -> 8.2 | M4: maize flour | N4: mustard greens | O4: winter greens | P4: slow-cooked and mashed | Q4: white butter on top | R4: eaten with corn flatbread | S4: Punjab's winter mustard-leaf mash, paired with makki di roti | T4: maize flour; mustard greens | V4: =COUNTA(M4:R4) -> 6 | W4: Yes | X4: Yes | Y4: Yes | AA4: https://commons.wikimedia.org/w/index.php?search=Sarson+da+Saag+food&title=Special:MediaSearch&type=image | AE4: Needed | AF4: Draft v2 - editorial check
A5: D0005 | B5: Amritsari Kulcha | D5: India | E5: Punjab | F5: Asia | G5: Southern Asia | H5: Bread | I5: Veg | J5: 2 | K5: 3 | L5: =INDEX('All Items'!$Q:$Q,MATCH($A5,'All Items'!$A:$A,0)) -> 7.15 | M5: potato | N5: ajwain | O5: tandoor | P5: stuffed flatbread | Q5: crisp layered crust | R5: served with chole | S5: Amritsar's stuffed, tandoor-baked bread with a crisp, buttery crust | T5: potato; ajwain | V5: =COUNTA(M5:R5) -> 6 | W5: No | X5: Yes | Y5: Yes | AA5: https://commons.wikimedia.org/w/index.php?search=Amritsari+Kulcha+food&title=Special:MediaSearch&type=image | AE5: Needed | AF5: Draft v2 - editorial check
A6: D0006 | B6: Dal Makhani | D6: India | E6: Punjab | F6: Asia | G6: Southern Asia | H6: Main | I6: Veg | J6: 1 | K6: 5 | L6: =INDEX('All Items'!$Q:$Q,MATCH($A6,'All Items'!$A:$A,0)) -> 10 | M6: butter | N6: kidney beans | O6: simmered overnight | P6: rich and creamy | Q6: dhaba favourite | R6: whole black urad dal | S6: Punjab's slow-cooked black lentils with butter and cream | T6: butter; kidney beans; whole black urad dal | U6: whole black urad dal | V6: =COUNTA(M6:R6) -> 6 | W6: Yes | X6: Yes | Y6: Yes | AA6: https://commons.wikimedia.org/w/index.php?search=Dal+Makhani+food&title=Special:MediaSearch&type=image | AE6: Needed | AF6: Draft v2 - editorial check
A7: D0007 | B7: Rajma Chawal | D7: India | E7: Punjab | F7: Asia | G7: Southern Asia | H7: Main | I7: Vegan | J7: 1 | K7: 5 | L7: =INDEX('All Items'!$Q:$Q,MATCH($A7,'All Items'!$A:$A,0)) -> 9.5 | M7: tomato | N7: rice | O7: kidney beans | P7: red beans in thick gravy | Q7: Sunday lunch staple | R7: served over steamed rice | S7: North India's comfort plate of kidney-bean curry over rice | T7: tomato; rice; kidney beans | V7: =COUNTA(M7:R7) -> 6 | W7: Yes | X7: Yes | Y7: Yes | AA7: https://commons.wikimedia.org/w/index.php?search=Rajma+Chawal+food&title=Special:MediaSearch&type=image | AE7: Needed | AF7: Draft v2 - editorial check
A8: D0008 | B8: Paneer Tikka | D8: India | E8: Punjab | F8: Asia | G8: Southern Asia | H8: Snack | I8: Veg | J8: 1 | K8: 5 | L8: =INDEX('All Items'!$Q:$Q,MATCH($A8,'All Items'!$A:$A,0)) -> 10 | M8: tandoori masala | N8: skewers | O8: marinated cubes | P8: charred edges | Q8: tandoor-grilled | R8: paneer | S8: Cottage cheese cubes marinated in spiced yogurt and grilled on skewers | T8: tandoori masala; paneer | U8: paneer | V8: =COUNTA(M8:R8) -> 6 | W8: Yes | X8: Yes | Y8: Yes | AA8: https://commons.wikimedia.org/w/index.php?search=Paneer+Tikka+food&title=Special:MediaSearch&type=image | AB8: https://thumb.wikimedia.org/wikipedia/commons/thumb/f/f2/Paneer_tikka.jpg/1280px-Paneer_tikka.jpg | AC8: CC BY-SA 4.0 | AD8: Meghana Mohanty | AE8: Candidate - review | AF8: Draft v2 - editorial check
A9: D0009 | B9: Tandoori Chicken | D9: India | E9: Punjab | F9: Asia | G9: Southern Asia | H9: Main | I9: Non-veg | J9: 1 | K9: 5 | L9: =INDEX('All Items'!$Q:$Q,MATCH($A9,'All Items'!$A:$A,0)) -> 10 | M9: kashmiri chilli | N9: tandoor | O9: bright red marinade | P9: charred on the bone | Q9: served with onion rings | R9: chicken | S9: Bone-in chicken marinated red and roasted in a clay oven | T9: kashmiri chilli; chicken | U9: chicken | V9: =COUNTA(M9:R9) -> 6 | W9: Yes | X9: Yes | Y9: Yes | AA9: https://commons.wikimedia.org/w/index.php?search=Tandoori+Chicken+food&title=Special:MediaSearch&type=image | AE9: Needed | AF9: Draft v2 - editorial check
A10: D0010 | B10: Amritsari Fish | D10: India | E10: Punjab | F10: Asia | G10: Southern Asia | H10: Snack | I10: Non-veg | J10: 2 | K10: 3 | L10: =INDEX('All Items'!$Q:$Q,MATCH($A10,'All Items'!$A:$A,0)) -> 7.4 | M10: carom seeds | N10: gram flour | O10: batter-fried | P10: carom-spiced crust | Q10: Amritsar street snack | R10: fish | S10: Fried fish in a spiced gram-flour batter from Amritsar | T10: carom seeds; gram flour; fish | U10: fish | V10: =COUNTA(M10:R10) -> 6 | W10: No | X10: Yes | Y10: Yes | AA10: https://commons.wikimedia.org/w/index.php?search=Amritsari+Fish+food&title=Special:MediaSearch&type=image | AE10: Needed | AF10: Draft v2 - editorial check
A11: D0012 | B11: Aloo Paratha | D11: India | E11: Punjab | F11: Asia | G11: Southern Asia | H11: Breakfast | I11: Veg | J11: 1 | K11: 5 | L11: =INDEX('All Items'!$Q:$Q,MATCH($A11,'All Items'!$A:$A,0)) -> 9 | M11: potato | N11: stuffed flatbread | O11: spiced mashed filling | P11: dollop of white butter | Q11: eaten with curd and pickle | S11: Punjab's favourite breakfast: flatbread stuffed with spiced mashed potato | T11: potato | V11: =COUNTA(M11:R11) -> 5 | W11: Yes | X11: Yes | Y11: Yes | AA11: https://commons.wikimedia.org/w/index.php?search=Aloo+Paratha+food&title=Special:MediaSearch&type=image | AE11: Needed | AF11: Draft v2 - editorial check
A12: D0014 | B12: Kadhi Pakora | D12: India | E12: Punjab | F12: Asia | G12: Southern Asia | H12: Main | I12: Veg | J12: 1 | K12: 4 | L12: =INDEX('All Items'!$Q:$Q,MATCH($A12,'All Items'!$A:$A,0)) -> 8.45 | M12: yogurt | N12: fenugreek seeds | O12: gram flour | P12: fritters | Q12: tangy yogurt curry | R12: served with rice | S12: A sour yogurt-and-gram-flour curry with onion fritters | T12: yogurt; fenugreek seeds; gram flour; fritters | V12: =COUNTA(M12:R12) -> 6 | W12: Yes | X12: Yes | Y12: Yes | AA12: https://commons.wikimedia.org/w/index.php?search=Kadhi+Pakora+food&title=Special:MediaSearch&type=image | AE12: Needed | AF12: Draft v2 - editorial check
A13: D0016 | B13: Paneer Butter Masala | D13: India | E13: Delhi | F13: Asia | G13: Southern Asia | H13: Main | I13: Veg | J13: 1 | K13: 5 | L13: =INDEX('All Items'!$Q:$Q,MATCH($A13,'All Items'!$A:$A,0)) -> 10 | M13: kasuri methi | N13: orange buttery gravy | O13: restaurant favourite | P13: vegetarian cousin of a famous chicken dish | Q13: paneer | R13: butter | S13: Cottage cheese in a rich, mildly sweet, buttery tomato gravy | T13: kasuri methi; paneer; butter | U13: paneer; butter | V13: =COUNTA(M13:R13) -> 6 | W13: Yes | X13: Yes | Y13: Yes | AA13: https://commons.wikimedia.org/w/index.php?search=Paneer+Butter+Masala+food&title=Special:MediaSearch&type=image | AB13: https://thumb.wikimedia.org/wikipedia/commons/thumb/a/ad/Shahi_panner.jpg/1280px-Shahi_panner.jpg | AC13: CC BY-SA 4.0 | AD13: Om shankar singh | AE13: Candidate - review | AF13: Draft v2 - editorial check
A14: D0017 | B14: Shahi Paneer | D14: India | E14: Delhi | F14: Asia | G14: Southern Asia | H14: Main | I14: Veg | J14: 1 | K14: 4 | L14: =INDEX('All Items'!$Q:$Q,MATCH($A14,'All Items'!$A:$A,0)) -> 8.7 | M14: cream | N14: cashew | O14: saffron | P14: royal Mughlai style | Q14: pale creamy gravy | R14: paneer | S14: Cottage cheese in a rich, nutty, saffron-scented cream gravy | T14: cream; cashew; saffron; paneer | U14: paneer | V14: =COUNTA(M14:R14) -> 6 | W14: Yes | X14: Yes | Y14: Yes | AA14: https://commons.wikimedia.org/w/index.php?search=Shahi+Paneer+food&title=Special:MediaSearch&type=image | AE14: Needed | AF14: Draft v2 - editorial check
A15: D0018 | B15: Kadai Paneer | D15: India | E15: Punjab | F15: Asia | G15: Southern Asia | H15: Main | I15: Veg | J15: 1 | K15: 4 | L15: =INDEX('All Items'!$Q:$Q,MATCH($A15,'All Items'!$A:$A,0)) -> 8.7 | M15: coriander seed | N15: capsicum | O15: wok-like iron pan | P15: chunky peppers | Q15: paneer | R15: kadai masala | S15: Cottage cheese and peppers tossed in a freshly ground spice mix in an iron wok | T15: coriander seed; capsicum; paneer; kadai masala | U15: paneer; kadai masala | V15: =COUNTA(M15:R15) -> 6 | W15: Yes | X15: Yes | Y15: Yes | AA15: https://commons.wikimedia.org/w/index.php?search=Kadai+Paneer+food&title=Special:MediaSearch&type=image | AE15: Needed | AF15: Draft v2 - editorial check
A16: D0019 | B16: Malai Kofta | D16: India | E16: Delhi | F16: Asia | G16: Southern Asia | H16: Main | I16: Veg | J16: 1 | K16: 5 | L16: =INDEX('All Items'!$Q:$Q,MATCH($A16,'All Items'!$A:$A,0)) -> 10 | M16: cashew | N16: raisins | O16: paneer dumplings | P16: fried dumplings | Q16: dumplings in cream gravy | R16: party dish | S16: Fried paneer-and-potato balls in a creamy cashew gravy | T16: cashew; raisins; paneer dumplings | V16: =COUNTA(M16:R16) -> 6 | W16: Yes | X16: Yes | Y16: Yes | AA16: https://commons.wikimedia.org/w/index.php?search=Malai+Kofta+food&title=Special:MediaSearch&type=image | AE16: Needed | AF16: Draft v2 - editorial check
A17: D0020 | B17: Chicken Tikka Masala | D17: India | E17: Punjab | F17: Asia | G17: Southern Asia | H17: Main | I17: Non-veg | J17: 1 | K17: 5 | L17: =INDEX('All Items'!$Q:$Q,MATCH($A17,'All Items'!$A:$A,0)) -> 9.75 | M17: cream | N17: tomato | O17: yogurt | P17: grilled chunks in creamy orange sauce | Q17: Britain's favourite curry | R17: grilled chicken | S17: Grilled chicken pieces in a creamy, spiced tomato sauce | T17: cream; tomato; yogurt; grilled chicken | U17: grilled chicken | V17: =COUNTA(M17:R17) -> 6 | W17: Yes | X17: Yes | Y17: No | Z17: Origin disputed between India and the UK (Glasgow) | AA17: https://commons.wikimedia.org/w/index.php?search=Chicken+Tikka+Masala+food&title=Special:MediaSearch&type=image | AB17: https://thumb.wikimedia.org/wikipedia/commons/thumb/0/00/Chicken_tikka_masala_%28cropped%29.jpg/1280px-Chicken_tikka_masala_%28cropped%29.jpg | AC17: CC BY 2.0 | AD17: Michael Hays | AE17: Candidate - review | AF17: Draft v2 - editorial check
A18: D0021 | B18: Seekh Kebab | D18: India | E18: Delhi | F18: Asia | G18: Southern Asia | H18: Snack | I18: Non-veg | J18: 1 | K18: 4 | L18: =INDEX('All Items'!$Q:$Q,MATCH($A18,'All Items'!$A:$A,0)) -> 8.2 | M18: mint | N18: skewers | O18: minced mutton | P18: long kebabs | Q18: cooked on skewers over coals | R18: green chutney on the side | S18: Spiced minced meat moulded on skewers and grilled | T18: mint; minced mutton | V18: =COUNTA(M18:R18) -> 6 | W18: Yes | X18: Yes | Y18: Yes | AA18: https://commons.wikimedia.org/w/index.php?search=Seekh+Kebab+food&title=Special:MediaSearch&type=image | AB18: https://thumb.wikimedia.org/wikipedia/commons/thumb/0/0c/Pakistani_Food_Beef_Kabobs.jpg/1280px-Pakistani_Food_Beef_Kabobs.jpg | AC18: CC BY 2.0 | AD18: Jess Lander from Culver City, CA, USA | AE18: Candidate - review | AF18: Draft v2 - editorial check
A19: D0022 | B19: Nihari | D19: India | E19: Delhi | F19: Asia | G19: Southern Asia | H19: Main | I19: Non-veg | J19: 1 | K19: 4 | L19: =INDEX('All Items'!$Q:$Q,MATCH($A19,'All Items'!$A:$A,0)) -> 8.7 | M19: bone marrow | N19: slow-cooked beef shank | O19: eaten at dawn | P19: sticky rich stew | Q19: Old Delhi breakfast | R19: nihari masala | S19: A slow-cooked meat stew eaten for breakfast in Old Delhi | T19: bone marrow; slow-cooked beef shank; nihari masala | U19: nihari masala | V19: =COUNTA(M19:R19) -> 6 | W19: Yes | X19: Yes | Y19: Yes | AA19: https://commons.wikimedia.org/w/index.php?search=Nihari+food&title=Special:MediaSearch&type=image | AE19: Needed | AF19: Draft v2 - editorial check
A20: D0024 | B20: Aloo Tikki | D20: India | E20: Delhi | F20: Asia | G20: Southern Asia | H20: Street | I20: Veg | J20: 1 | K20: 5 | L20: =INDEX('All Items'!$Q:$Q,MATCH($A20,'All Items'!$A:$A,0)) -> 10 | M20: tamarind chutney | N20: breadcrumbs | O20: potato patty | P20: crispy fried patty | Q20: chaat topping | R20: street snack | S20: Crisp shallow-fried potato patties topped with chutneys and yogurt | T20: tamarind chutney; breadcrumbs; potato patty | V20: =COUNTA(M20:R20) -> 6 | W20: Yes | X20: Yes | Y20: Yes | AA20: https://commons.wikimedia.org/w/index.php?search=Aloo+Tikki+food&title=Special:MediaSearch&type=image | AE20: Needed | AF20: Draft v2 - editorial check
A21: D0025 | B21: Papdi Chaat | D21: India | E21: Delhi | F21: Asia | G21: Southern Asia | H21: Street | I21: Veg | J21: 1 | K21: 4 | L21: =INDEX('All Items'!$Q:$Q,MATCH($A21,'All Items'!$A:$A,0)) -> 8.7 | M21: tamarind chutney | N21: crisp fried wafers | O21: chaat topping | P21: sweet, sour and spicy | Q21: chaat masala | R21: papdi | S21: Crisp wafers topped with potato, chickpeas, yogurt and chutneys | T21: tamarind chutney; chaat masala; papdi | U21: chaat topping; chaat masala; papdi | V21: =COUNTA(M21:R21) -> 6 | W21: Yes | X21: Yes | Y21: Yes | AA21: https://commons.wikimedia.org/w/index.php?search=Papdi+Chaat+food&title=Special:MediaSearch&type=image | AE21: Needed | AF21: Draft v2 - editorial check
A22: D0026 | B22: Dahi Bhalla | D22: India | E22: Delhi | F22: Asia | G22: Southern Asia | H22: Street | I22: Veg | J22: 1 | K22: 4 | L22: =INDEX('All Items'!$Q:$Q,MATCH($A22,'All Items'!$A:$A,0)) -> 8.7 | M22: tamarind chutney | N22: urad dal | O22: lentil dumplings | P22: soaked dumplings | Q22: cool and tangy | R22: Holi favourite | S22: Soft lentil dumplings soaked in yogurt with sweet tamarind chutney | T22: tamarind chutney; urad dal; lentil dumplings | V22: =COUNTA(M22:R22) -> 6 | W22: Yes | X22: Yes | Y22: Yes | AA22: https://commons.wikimedia.org/w/index.php?search=Dahi+Bhalla+food&title=Special:MediaSearch&type=image | AE22: Needed | AF22: Draft v2 - editorial check
A23: D0029 | B23: Chole Kulche | D23: India | E23: Delhi | F23: Asia | G23: Southern Asia | H23: Street | I23: Vegan | J23: 2 | K23: 3 | L23: =INDEX('All Items'!$Q:$Q,MATCH($A23,'All Items'!$A:$A,0)) -> 7.15 | M23: lemon | N23: chickpeas | O23: tamarind | P23: kulcha | Q23: leavened bread | R23: Delhi street plate | S23: Delhi's street plate of soft bread with tangy white-pea or chickpea curry | T23: lemon; chickpeas; tamarind; kulcha | V23: =COUNTA(M23:R23) -> 6 | W23: No | X23: Yes | Y23: Yes | AA23: https://commons.wikimedia.org/w/index.php?search=Chole+Kulche+food&title=Special:MediaSearch&type=image | AE23: Needed | AF23: Draft v2 - editorial check
A24: D0031 | B24: Jalebi | D24: India | E24: Delhi | F24: Asia | G24: Southern Asia | H24: Sweet | I24: Veg | J24: 1 | K24: 5 | L24: =INDEX('All Items'!$Q:$Q,MATCH($A24,'All Items'!$A:$A,0)) -> 9.25 | M24: saffron | N24: spiral | O24: deep fried in ghee | P24: soaked in syrup | Q24: bright orange coils | S24: Crisp orange spirals fried and soaked in sugar syrup | T24: saffron | V24: =COUNTA(M24:R24) -> 5 | W24: Yes | X24: Yes | Y24: No | Z24: West Asian origin, shared across South Asia | AA24: https://commons.wikimedia.org/w/index.php?search=Jalebi+food&title=Special:MediaSearch&type=image | AB24: https://thumb.wikimedia.org/wikipedia/commons/thumb/9/96/Basavanagudi_Kadalekai_Parishe_%282025%29_Bangalore_%2886%29.jpg/1280px-Basavanagudi_Kadalekai_Parishe_%282025%29_Bangalore_%2886%29.jpg | AC24: CC BY-SA 4.0 | AD24: Gpkp | AE24: Candidate - review | AF24: Draft v2 - editorial check
A25: D0032 | B25: Rabri | D25: India | E25: Uttar Pradesh | F25: Asia | G25: Southern Asia | H25: Sweet | I25: Veg | J25: 2 | K25: 3 | L25: =INDEX('All Items'!$Q:$Q,MATCH($A25,'All Items'!$A:$A,0)) -> 7.15 | M25: pistachio | N25: saffron | O25: thickened milk layers | P25: layered milk skins | Q25: slowly reduced | R25: served chilled | S25: Milk slowly reduced to thick, sweet layers of cream | T25: pistachio; saffron | V25: =COUNTA(M25:R25) -> 6 | W25: No | X25: Yes | Y25: Yes | AA25: https://commons.wikimedia.org/w/index.php?search=Rabri+food&title=Special:MediaSearch&type=image | AB25: https://thumb.wikimedia.org/wikipedia/commons/thumb/b/bb/Homemade_Rabri.jpg/1280px-Homemade_Rabri.jpg | AC25: CC BY-SA 4.0 | AD25: Ravi Talwar | AE25: Candidate - review | AF25: Draft v2 - editorial check
A26: D0033 | B26: Kachori | D26: India | E26: Rajasthan | F26: Asia | G26: Southern Asia | H26: Snack | I26: Vegan | J26: 1 | K26: 4 | L26: =INDEX('All Items'!$Q:$Q,MATCH($A26,'All Items'!$A:$A,0)) -> 8.45 | M26: asafoetida | N26: moong dal | O26: deep fried | P26: deep-fried round pastry | Q26: spiced lentil filling | R26: flaky shell | S26: A flaky fried pastry ball stuffed with spiced lentils | T26: asafoetida; moong dal | V26: =COUNTA(M26:R26) -> 6 | W26: Yes | X26: Yes | Y26: Yes | AA26: https://commons.wikimedia.org/w/index.php?search=Kachori+food&title=Special:MediaSearch&type=image | AE26: Needed | AF26: Draft v2 - editorial check
A27: D0034 | B27: Lucknowi Biryani | C27: Awadhi Biryani | D27: India | E27: Uttar Pradesh | F27: Asia | G27: Southern Asia | H27: Rice | I27: Non-veg | J27: 1 | K27: 4 | L27: =INDEX('All Items'!$Q:$Q,MATCH($A27,'All Items'!$A:$A,0)) -> 8.7 | M27: saffron | N27: basmati rice | O27: mutton | P27: dum cooking | Q27: fragrant layered rice | R27: sealed pot | S27: Lucknow's delicate, fragrant layered rice with meat | T27: saffron; basmati rice; mutton | V27: =COUNTA(M27:R27) -> 6 | W27: Yes | X27: Yes | Y27: Yes | AA27: https://commons.wikimedia.org/w/index.php?search=Lucknowi+Biryani+food&title=Special:MediaSearch&type=image | AE27: Needed | AF27: Draft v2 - editorial check
A28: D0035 | B28: Galouti Kebab | D28: India | E28: Uttar Pradesh | F28: Asia | G28: Southern Asia | H28: Snack | I28: Non-veg | J28: 1 | K28: 4 | L28: =INDEX('All Items'!$Q:$Q,MATCH($A28,'All Items'!$A:$A,0)) -> 8.7 | M28: raw papaya | N28: minced mutton | O28: melt-in-mouth | P28: so soft it melts | Q28: Lucknow | R28: made for a toothless nawab | S28: Lucknow's ultra-soft minced-meat patty | T28: raw papaya; minced mutton | V28: =COUNTA(M28:R28) -> 6 | W28: Yes | X28: Yes | Y28: Yes | AA28: https://commons.wikimedia.org/w/index.php?search=Galouti+Kebab+food&title=Special:MediaSearch&type=image | AB28: https://thumb.wikimedia.org/wikipedia/commons/thumb/8/88/Tunday_Kebabs.jpg/1280px-Tunday_Kebabs.jpg | AC28: CC BY-SA 4.0 | AD28: Lillottama | AE28: Candidate - review | AF28: Draft v2 - editorial check
A29: D0036 | B29: Kakori Kebab | D29: India | E29: Uttar Pradesh | F29: Asia | G29: Southern Asia | H29: Snack | I29: Non-veg | J29: 2 | K29: 3 | L29: =INDEX('All Items'!$Q:$Q,MATCH($A29,'All Items'!$A:$A,0)) -> 7.4 | M29: kewra | N29: skewers | O29: minced mutton | P29: long, thin kebabs | Q29: Lucknow | R29: silky texture | S29: Lucknow's silky minced-meat skewers | T29: kewra; minced mutton | V29: =COUNTA(M29:R29) -> 6 | W29: No | X29: Yes | Y29: Yes | AA29: https://commons.wikimedia.org/w/index.php?search=Kakori+Kebab+food&title=Special:MediaSearch&type=image | AB29: https://thumb.wikimedia.org/wikipedia/commons/thumb/5/5b/Lula_kebab_2.jpg/1280px-Lula_kebab_2.jpg | AC29: CC BY-SA 2.0 | AD29: Lesya Dolyk | AE29: Candidate - review | AF29: Draft v2 - editorial check
A30: D0038 | B30: Korma | D30: India | E30: Uttar Pradesh | F30: Asia | G30: Southern Asia | H30: Main | I30: Non-veg | J30: 1 | K30: 4 | L30: =INDEX('All Items'!$Q:$Q,MATCH($A30,'All Items'!$A:$A,0)) -> 8.7 | M30: yogurt | N30: cashew | O30: mutton | P30: fried onion paste | Q30: Mughlai | R30: mild nutty gravy | S30: A mild, rich Mughlai curry of meat braised in yogurt and nuts | T30: yogurt; cashew; mutton; fried onion paste | V30: =COUNTA(M30:R30) -> 6 | W30: Yes | X30: Yes | Y30: Yes | AA30: https://commons.wikimedia.org/w/index.php?search=Korma+food&title=Special:MediaSearch&type=image | AB30: https://thumb.wikimedia.org/wikipedia/commons/thumb/a/a8/Chicken_Korma.JPG/1280px-Chicken_Korma.JPG | AC30: CC0 | AD30: Miansari66 | AE30: Candidate - review | AF30: Draft v2 - editorial check
A31: D0040 | B31: Kulfi | D31: India | E31: Uttar Pradesh | F31: Asia | G31: Southern Asia | H31: Dessert | I31: Veg | J31: 1 | K31: 5 | L31: =INDEX('All Items'!$Q:$Q,MATCH($A31,'All Items'!$A:$A,0)) -> 10 | M31: saffron | N31: reduced milk | O31: matka | P31: frozen in cones | Q31: dense not airy | R31: sold on a stick | S31: Dense frozen milk dessert set in cone-shaped moulds | T31: saffron; reduced milk | V31: =COUNTA(M31:R31) -> 6 | W31: Yes | X31: Yes | Y31: Yes | AA31: https://commons.wikimedia.org/w/index.php?search=Kulfi+food&title=Special:MediaSearch&type=image | AE31: Needed | AF31: Draft v2 - editorial check
A32: D0041 | B32: Bedmi Puri | D32: India | E32: Uttar Pradesh | F32: Asia | G32: Southern Asia | H32: Breakfast | I32: Vegan | J32: 2 | K32: 3 | L32: =INDEX('All Items'!$Q:$Q,MATCH($A32,'All Items'!$A:$A,0)) -> 7.15 | M32: fennel | N32: potato curry | O32: wheat flour | P32: urad dal stuffing | Q32: deep-fried bread | R32: Uttar Pradesh breakfast | S32: Lentil-stuffed fried bread with spicy potato curry | T32: fennel; potato curry; wheat flour; urad dal stuffing | V32: =COUNTA(M32:R32) -> 6 | W32: No | X32: Yes | Y32: Yes | AA32: https://commons.wikimedia.org/w/index.php?search=Bedmi+Puri+food&title=Special:MediaSearch&type=image | AE32: Needed | AF32: Draft v2 - editorial check
A33: D0042 | B33: Petha | D33: India | E33: Uttar Pradesh | F33: Asia | G33: Southern Asia | H33: Sweet | I33: Vegan | J33: 2 | K33: 3 | L33: =INDEX('All Items'!$Q:$Q,MATCH($A33,'All Items'!$A:$A,0)) -> 7.15 | M33: lime | N33: kewra | O33: ash gourd | P33: translucent candy | Q33: Agra sweet | R33: Agra | S33: Agra's translucent candied gourd sweet | T33: lime; kewra; ash gourd | V33: =COUNTA(M33:R33) -> 6 | W33: No | X33: Yes | Y33: Yes | AA33: https://commons.wikimedia.org/w/index.php?search=Petha+food&title=Special:MediaSearch&type=image | AB33: https://thumb.wikimedia.org/wikipedia/commons/thumb/b/bc/Petha_kesari.JPG/1280px-Petha_kesari.JPG | AC33: CC BY-SA 4.0 | AD33: PJ.wikilovesfood | AE33: Candidate - review | AF33: Draft v2 - editorial check
A34: D0044 | B34: Banarasi Paan | D34: India | E34: Uttar Pradesh | F34: Asia | G34: Southern Asia | H34: Snack | I34: Vegan | J34: 2 | K34: 4 | L34: =INDEX('All Items'!$Q:$Q,MATCH($A34,'All Items'!$A:$A,0)) -> 8.7 | M34: fennel | N34: areca nut | O34: betel leaf | P34: chewed after a meal | Q34: folded into a triangle | R34: Varanasi | S34: Varanasi's famous after-dinner betel-leaf parcel | T34: fennel; areca nut; betel leaf | V34: =COUNTA(M34:R34) -> 6 | W34: No | X34: Yes | Y34: Yes | AA34: https://commons.wikimedia.org/w/index.php?search=Banarasi+Paan+food&title=Special:MediaSearch&type=image | AE34: Needed | AF34: Draft v2 - editorial check
A35: D0046 | B35: Litti Chokha | D35: India | E35: Bihar | F35: Asia | G35: Southern Asia | H35: Main | I35: Veg | J35: 1 | K35: 4 | L35: =INDEX('All Items'!$Q:$Q,MATCH($A35,'All Items'!$A:$A,0)) -> 8.7 | M35: aubergine | N35: roasted dough balls | O35: sattu | P35: roasted gram-flour balls | Q35: smoky mash | R35: Bihar | S35: Bihar's roasted stuffed dough balls with smoky mashed vegetables | T35: aubergine; roasted dough balls; sattu | V35: =COUNTA(M35:R35) -> 6 | W35: Yes | X35: Yes | Y35: Yes | AA35: https://commons.wikimedia.org/w/index.php?search=Litti+Chokha+food&title=Special:MediaSearch&type=image | AB35: https://thumb.wikimedia.org/wikipedia/commons/thumb/a/ae/Litti_Chokha_2.jpg/1280px-Litti_Chokha_2.jpg | AC35: CC BY-SA 4.0 | AD35: Eddie Stann | AE35: Candidate - review | AF35: Draft v2 - editorial check
A36: D0047 | B36: Thekua | D36: India | E36: Bihar | F36: Asia | G36: Southern Asia | H36: Sweet | I36: Vegan | J36: 2 | K36: 3 | L36: =INDEX('All Items'!$Q:$Q,MATCH($A36,'All Items'!$A:$A,0)) -> 7.4 | M36: wheat flour | N36: jaggery | O36: Chhath festival | P36: festival cookie | Q36: deep-fried | R36: carved mould pattern | S36: Bihar's crunchy jaggery cookie made for Chhath | T36: wheat flour; jaggery | V36: =COUNTA(M36:R36) -> 6 | W36: No | X36: Yes | Y36: Yes | AA36: https://commons.wikimedia.org/w/index.php?search=Thekua+food&title=Special:MediaSearch&type=image | AB36: https://thumb.wikimedia.org/wikipedia/commons/thumb/9/9c/Thekua_-_Chhath_Festival_-_Kolkata_2013-11-09_4316.JPG/1280px-Thekua_-_Chhath_Festival_-_Kolkata_2013-11-09_4316.JPG | AC36: CC BY 3.0 | AD36: Biswarup Ganguly | AE36: Candidate - review | AF36: Draft v2 - editorial check
A37: D0050 | B37: Dal Baati Churma | D37: India | E37: Rajasthan | F37: Asia | G37: Southern Asia | H37: Main | I37: Veg | J37: 1 | K37: 4 | L37: =INDEX('All Items'!$Q:$Q,MATCH($A37,'All Items'!$A:$A,0)) -> 7.95 | M37: lentils | N37: baked dough balls | O37: three-part platter | P37: ghee-dipped | Q37: crushed sweet crumble | S37: Rajasthan's platter of baked dough balls, lentils and a sweet crumble | T37: lentils; baked dough balls | V37: =COUNTA(M37:R37) -> 5 | W37: Yes | X37: Yes | Y37: Yes | AA37: https://commons.wikimedia.org/w/index.php?search=Dal+Baati+Churma+food&title=Special:MediaSearch&type=image | AE37: Needed | AF37: Draft v2 - editorial check
A38: D0051 | B38: Laal Maas | D38: India | E38: Rajasthan | F38: Asia | G38: Southern Asia | H38: Main | I38: Non-veg | J38: 1 | K38: 4 | L38: =INDEX('All Items'!$Q:$Q,MATCH($A38,'All Items'!$A:$A,0)) -> 8.2 | M38: yogurt | N38: mutton | O38: mathania chilli | P38: fiery red curry | Q38: Rajput hunting dish | R38: smoky | S38: Rajasthan's fiery red mutton curry | T38: yogurt; mutton; mathania chilli | V38: =COUNTA(M38:R38) -> 6 | W38: Yes | X38: Yes | Y38: Yes | AA38: https://commons.wikimedia.org/w/index.php?search=Laal+Maas+food&title=Special:MediaSearch&type=image | AE38: Needed | AF38: Draft v2 - editorial check
A39: D0052 | B39: Gatte ki Sabzi | D39: India | E39: Rajasthan | F39: Asia | G39: Southern Asia | H39: Main | I39: Veg | J39: 1 | K39: 4 | L39: =INDEX('All Items'!$Q:$Q,MATCH($A39,'All Items'!$A:$A,0)) -> 8.45 | M39: ajwain | N39: steamed | O39: gram flour dumplings | P39: steamed dumplings | Q39: yogurt gravy | R39: desert cooking | S39: Rajasthan's gram-flour dumplings in a tangy yogurt curry | T39: ajwain; gram flour dumplings | V39: =COUNTA(M39:R39) -> 6 | W39: Yes | X39: Yes | Y39: Yes | AA39: https://commons.wikimedia.org/w/index.php?search=Gatte+ki+Sabzi+food&title=Special:MediaSearch&type=image | AE39: Needed | AF39: Draft v2 - editorial check
A40: D0053 | B40: Ker Sangri | D40: India | E40: Rajasthan | F40: Asia | G40: Southern Asia | H40: Side | I40: Vegan | J40: 2 | K40: 3 | L40: =INDEX('All Items'!$Q:$Q,MATCH($A40,'All Items'!$A:$A,0)) -> 6.9 | M40: dried mango powder | N40: desert beans | O40: capers | P40: dried desert produce | Q40: tangy and spicy | R40: Marwari | S40: A dry Rajasthani dish of desert beans and berries | T40: dried mango powder; desert beans; capers | V40: =COUNTA(M40:R40) -> 6 | W40: No | X40: Yes | Y40: Yes | AA40: https://commons.wikimedia.org/w/index.php?search=Ker+Sangri+food&title=Special:MediaSearch&type=image | AE40: Needed | AF40: Draft v2 - editorial check
...

Sheet Drinks
A1: ID | B1: Drink | C1: Also known as | D1: Country | E1: State / region | F1: Continent | G1: Subregion | H1: Type | I1: Alcoholic | J1: Glass / serve | K1: Fame (1-3) | L1: Recognition (1-5) | M1: Score | N1: Clue 1 | O1: Clue 2 | P1: Clue 3 | Q1: Clue 4 | R1: Clue 5 | S1: Clue 6 | T1: Final hint | U1: Ingredient clues | V1: Giveaway clues (shown last) | W1: Clue count | X1: Global mode | Y1: India mode | Z1: Country mode | AA1: Origin note | AB1: Image search (Wikimedia) | AC1: Image URL | AD1: Image licence | AE1: Image credit | AF1: Image status | AG1: Status
A2: B0001 | B2: Mojito | D2: Cuba | F2: Americas | G2: Caribbean | H2: Cocktail | I2: Yes | J2: Highball | K2: 1 | L2: 5 | M2: =INDEX('All Items'!$Q:$Q,MATCH($A2,'All Items'!$A:$A,0)) -> 9.75 | N2: soda water | O2: lime | P2: white rum | Q2: mint | R2: Cuban highball | S2: minty | T2: Cuba's minty rum highball | U2: soda water; lime; white rum; mint | W2: =COUNTA(N2:S2) -> 6 | X2: Yes | Y2: No | Z2: Yes | AB2: https://commons.wikimedia.org/w/index.php?search=Mojito+drink&title=Special:MediaSearch&type=image | AC2: https://thumb.wikimedia.org/wikipedia/commons/thumb/5/54/15-09-26-RalfR-WLC-0072.jpg/1280px-15-09-26-RalfR-WLC-0072.jpg | AD2: CC BY-SA 3.0 | AE2: Ralf Roletschek | AF2: Candidate - review | AG2: Draft v2 - editorial check
A3: B0002 | B3: Margarita | D3: Mexico | F3: Americas | G3: North America | H3: Cocktail | I3: Yes | J3: Coupe or margarita glass | K3: 1 | L3: 5 | M3: =INDEX('All Items'!$Q:$Q,MATCH($A3,'All Items'!$A:$A,0)) -> 9.75 | N3: lime | O3: salt rim | P3: triple sec | Q3: tequila | R3: salted rim | S3: Mexican | T3: Mexico's tequila-lime cocktail with a salted rim | U3: lime; triple sec; tequila | W3: =COUNTA(N3:S3) -> 6 | X3: Yes | Y3: No | Z3: Yes | AB3: https://commons.wikimedia.org/w/index.php?search=Margarita+drink&title=Special:MediaSearch&type=image | AF3: Needed | AG3: Draft v2 - editorial check
A4: B0003 | B4: Piña Colada | D4: Puerto Rico | F4: Americas | G4: Caribbean | H4: Cocktail | I4: Yes | J4: Hurricane | K4: 1 | L4: 5 | M4: =INDEX('All Items'!$Q:$Q,MATCH($A4,'All Items'!$A:$A,0)) -> 9.75 | N4: cream of coconut | O4: white rum | P4: blended | Q4: pineapple juice | R4: creamy tropical | S4: Puerto Rico | T4: Puerto Rico's creamy coconut-pineapple rum cocktail | U4: cream of coconut; white rum; pineapple juice | W4: =COUNTA(N4:S4) -> 6 | X4: Yes | Y4: No | Z4: Yes | AB4: https://commons.wikimedia.org/w/index.php?search=Pi%C3%B1a+Colada+drink&title=Special:MediaSearch&type=image | AF4: Needed | AG4: Draft v2 - editorial check
A5: B0004 | B5: Old Fashioned | D5: United States | F5: Americas | G5: North America | H5: Cocktail | I5: Yes | J5: Rocks glass | K5: 1 | L5: 4 | M5: =INDEX('All Items'!$Q:$Q,MATCH($A5,'All Items'!$A:$A,0)) -> 8.2 | N5: orange peel | O5: angostura bitters | P5: bourbon | Q5: stirred whiskey | R5: sugar and bitters | T5: A stirred whiskey drink with sugar and bitters | U5: orange peel; angostura bitters; bourbon | W5: =COUNTA(N5:S5) -> 5 | X5: Yes | Y5: No | Z5: Yes | AB5: https://commons.wikimedia.org/w/index.php?search=Old+Fashioned+drink&title=Special:MediaSearch&type=image | AF5: Needed | AG5: Draft v2 - editorial check
A6: B0005 | B6: Martini | D6: United States | F6: Americas | G6: North America | H6: Cocktail | I6: Yes | J6: Martini glass | K6: 1 | L6: 4 | M6: =INDEX('All Items'!$Q:$Q,MATCH($A6,'All Items'!$A:$A,0)) -> 8.45 | N6: stirred | O6: olives | P6: dry vermouth | Q6: gin | R6: cocktail glass | S6: James Bond | T6: A stirred gin and vermouth cocktail | U6: olives; dry vermouth; gin | W6: =COUNTA(N6:S6) -> 6 | X6: Yes | Y6: No | Z6: Yes | AB6: https://commons.wikimedia.org/w/index.php?search=Martini+drink&title=Special:MediaSearch&type=image | AF6: Needed | AG6: Draft v2 - editorial check
A7: B0006 | B7: Negroni | D7: Italy | F7: Europe | G7: Southern Europe | H7: Cocktail | I7: Yes | J7: Rocks glass | K7: 1 | L7: 4 | M7: =INDEX('All Items'!$Q:$Q,MATCH($A7,'All Items'!$A:$A,0)) -> 8.45 | N7: orange peel | O7: sweet vermouth | P7: gin | Q7: campari | R7: bitter red | S7: equal parts | T7: Italy's bitter red cocktail in equal parts | U7: orange peel; sweet vermouth; gin; campari | W7: =COUNTA(N7:S7) -> 6 | X7: Yes | Y7: No | Z7: Yes | AB7: https://commons.wikimedia.org/w/index.php?search=Negroni+drink&title=Special:MediaSearch&type=image | AF7: Needed | AG7: Draft v2 - editorial check
A8: B0007 | B8: Cosmopolitan | D8: United States | F8: Americas | G8: North America | H8: Cocktail | I8: Yes | J8: Martini glass | K8: 1 | L8: 4 | M8: =INDEX('All Items'!$Q:$Q,MATCH($A8,'All Items'!$A:$A,0)) -> 8.45 | N8: lime | O8: triple sec | P8: citrus vodka | Q8: cranberry juice | R8: pink cocktail | S8: Sex and the City | T8: A pink vodka-cranberry cocktail | U8: lime; triple sec; citrus vodka; cranberry juice | W8: =COUNTA(N8:S8) -> 6 | X8: Yes | Y8: No | Z8: Yes | AB8: https://commons.wikimedia.org/w/index.php?search=Cosmopolitan+drink&title=Special:MediaSearch&type=image | AF8: Needed | AG8: Draft v2 - editorial check
A9: B0008 | B9: Daiquiri | D9: Cuba | F9: Americas | G9: Caribbean | H9: Cocktail | I9: Yes | J9: Coupe | K9: 1 | L9: 4 | M9: =INDEX('All Items'!$Q:$Q,MATCH($A9,'All Items'!$A:$A,0)) -> 8.2 | N9: lime | O9: shaken | P9: white rum | Q9: Cuban rum sour | R9: sugar | S9: coupe glass | T9: Cuba's rum, lime and sugar cocktail | U9: lime; white rum; sugar | W9: =COUNTA(N9:S9) -> 6 | X9: Yes | Y9: No | Z9: Yes | AB9: https://commons.wikimedia.org/w/index.php?search=Daiquiri+drink&title=Special:MediaSearch&type=image | AC9: https://thumb.wikimedia.org/wikipedia/commons/thumb/f/fd/Classic_Daiquiri_in_Cocktail_Glass.jpg/1280px-Classic_Daiquiri_in_Cocktail_Glass.jpg | AD9: CC BY-SA 3.0 | AE9: Will Shenton | AF9: Candidate - review | AG9: Draft v2 - editorial check
A10: B0009 | B10: Manhattan | D10: United States | F10: Americas | G10: North America | H10: Cocktail | I10: Yes | J10: Coupe | K10: 1 | L10: 4 | M10: =INDEX('All Items'!$Q:$Q,MATCH($A10,'All Items'!$A:$A,0)) -> 8.45 | N10: cherry | O10: angostura bitters | P10: sweet vermouth | Q10: rye whiskey | R10: stirred whiskey | S10: New York | T10: A stirred whiskey and sweet vermouth cocktail | U10: cherry; angostura bitters; sweet vermouth; rye whiskey | W10: =COUNTA(N10:S10) -> 6 | X10: Yes | Y10: No | Z10: Yes | AB10: https://commons.wikimedia.org/w/index.php?search=Manhattan+drink&title=Special:MediaSearch&type=image | AC10: https://thumb.wikimedia.org/wikipedia/commons/thumb/7/7a/View_of_Empire_State_Building_from_Rockefeller_Center_New_York_City_dllu_%28cropped%29.jpg/1280px-View_of_Empire_State_Building_from_Rockefeller_Center_New_York_City_dllu_%28cropped%29.jpg | AD10: CC BY-SA 4.0 | AE10: Dllu | AF10: Candidate - review | AG10: Draft v2 - editorial check
A11: B0010 | B11: Bloody Mary | D11: France | F11: Europe | G11: Western Europe | H11: Cocktail | I11: Yes | J11: Highball | K11: 1 | L11: 4 | M11: =INDEX('All Items'!$Q:$Q,MATCH($A11,'All Items'!$A:$A,0)) -> 8.7 | N11: celery | O11: Worcestershire sauce | P11: tabasco | Q11: vodka | R11: tomato juice | S11: savoury brunch cocktail | T11: A savoury vodka and tomato cocktail | U11: celery; Worcestershire sauce; tabasco; vodka; tomato juice | W11: =COUNTA(N11:S11) -> 6 | X11: Yes | Y11: No | Z11: No | AA11: Paris (Harry's New York Bar) and New York claims | AB11: https://commons.wikimedia.org/w/index.php?search=Bloody+Mary+drink&title=Special:MediaSearch&type=image | AF11: Needed | AG11: Draft v2 - editorial check
A12: B0011 | B12: Moscow Mule | D12: United States | F12: Americas | G12: North America | H12: Cocktail | I12: Yes | J12: Copper mug | K12: 1 | L12: 4 | M12: =INDEX('All Items'!$Q:$Q,MATCH($A12,'All Items'!$A:$A,0)) -> 8.45 | N12: ginger beer | O12: vodka | P12: copper mug | Q12: sugar | R12: mint sprig | S12: highball | T12: A vodka and ginger beer cocktail in a copper mug | U12: ginger beer; vodka | W12: =COUNTA(N12:S12) -> 6 | X12: Yes | Y12: No | Z12: Yes | AB12: https://commons.wikimedia.org/w/index.php?search=Moscow+Mule+drink&title=Special:MediaSearch&type=image | AC12: https://thumb.wikimedia.org/wikipedia/commons/thumb/8/89/Cocktail_Moscow_Mule_im_Kupferbecher_mit_Minze.jpg/1280px-Cocktail_Moscow_Mule_im_Kupferbecher_mit_Minze.jpg | AD12: CC BY-SA 4.0 | AE12: Gordito1869 | AF12: Candidate - review | AG12: Draft v2 - editorial check
A13: B0012 | B13: Whiskey Sour | D13: United States | F13: Americas | G13: North America | H13: Cocktail | I13: Yes | J13: Rocks glass | K13: 1 | L13: 4 | M13: =INDEX('All Items'!$Q:$Q,MATCH($A13,'All Items'!$A:$A,0)) -> 8.2 | N13: lemon | O13: egg white | P13: whisky | Q13: frothy sour | R13: bourbon | S13: angostura | T13: A frothy cocktail of bourbon, lemon and sugar | U13: lemon; egg white; whisky | V13: frothy sour | W13: =COUNTA(N13:S13) -> 6 | X13: Yes | Y13: No | Z13: Yes | AB13: https://commons.wikimedia.org/w/index.php?search=Whiskey+Sour+drink&title=Special:MediaSearch&type=image | AC13: https://thumb.wikimedia.org/wikipedia/commons/thumb/5/59/Whiskey_Sour.jpg/1280px-Whiskey_Sour.jpg | AD13: CC BY-SA 3.0 | AE13: Jgilgamesh | AF13: Candidate - review | AG13: Draft v2 - editorial check
A14: B0013 | B14: Mai Tai | D14: United States | F14: Americas | G14: North America | H14: Cocktail | I14: Yes | J14: Rocks glass | K14: 2 | L14: 3 | M14: =INDEX('All Items'!$Q:$Q,MATCH($A14,'All Items'!$A:$A,0)) -> 7.15 | N14: lime | O14: orgeat | P14: orange curaçao | Q14: dark rum | R14: tiki cocktail | T14: A tiki rum cocktail with almond syrup | U14: lime; orgeat; orange curaçao; dark rum | W14: =COUNTA(N14:S14) -> 5 | X14: Yes | Y14: No | Z14: Yes | AB14: https://commons.wikimedia.org/w/index.php?search=Mai+Tai+drink&title=Special:MediaSearch&type=image | AC14: https://thumb.wikimedia.org/wikipedia/commons/thumb/1/13/Mai_Tai_at_Trader_Vic%27s_Emeryville.jpg/1280px-Mai_Tai_at_Trader_Vic%27s_Emeryville.jpg | AD14: CC BY-SA 4.0 | AE14: Kevdo | AF14: Candidate - review | AG14: Draft v2 - editorial check
A15: B0014 | B15: Long Island Iced Tea | D15: United States | F15: Americas | G15: North America | H15: Cocktail | I15: Yes | J15: Highball | K15: 1 | L15: 5 | M15: =INDEX('All Items'!$Q:$Q,MATCH($A15,'All Items'!$A:$A,0)) -> 10 | N15: rum | O15: tequila | P15: gin | Q15: cola | R15: tastes like tea | S15: no tea | T15: A strong mix of four spirits topped with cola | U15: rum; tequila; gin; cola | V15: tastes like tea; no tea | W15: =COUNTA(N15:S15) -> 6 | X15: Yes | Y15: No | Z15: Yes | AB15: https://commons.wikimedia.org/w/index.php?search=Long+Island+Iced+Tea+drink&title=Special:MediaSearch&type=image | AF15: Needed | AG15: Draft v2 - editorial check
A16: B0015 | B16: Aperol Spritz | D16: Italy | F16: Europe | G16: Southern Europe | H16: Cocktail | I16: Yes | J16: Wine glass | K16: 1 | L16: 4 | M16: =INDEX('All Items'!$Q:$Q,MATCH($A16,'All Items'!$A:$A,0)) -> 8.45 | N16: soda water | O16: orange slice | P16: prosecco | Q16: Italian aperitivo | R16: aperol | T16: Italy's orange aperitivo with prosecco and soda | U16: soda water; orange slice; prosecco; aperol | V16: aperol | W16: =COUNTA(N16:S16) -> 5 | X16: Yes | Y16: No | Z16: Yes | AB16: https://commons.wikimedia.org/w/index.php?search=Aperol+Spritz+drink&title=Special:MediaSearch&type=image | AC16: https://thumb.wikimedia.org/wikipedia/commons/thumb/5/5f/Aperol_Spritz_aboard_Viking_Mariella.jpg/1280px-Aperol_Spritz_aboard_Viking_Mariella.jpg | AD16: CC BY-SA 4.0 | AE16: JIP | AF16: Candidate - review | AG16: Draft v2 - editorial check
A17: B0016 | B17: Caipirinha | D17: Brazil | F17: Americas | G17: South America | H17: Cocktail | I17: Yes | J17: Rocks glass | K17: 1 | L17: 4 | M17: =INDEX('All Items'!$Q:$Q,MATCH($A17,'All Items'!$A:$A,0)) -> 7.95 | N17: muddled lime | O17: cachaça | P17: Brazil's national cocktail | Q17: sugar | R17: crushed ice | T17: Brazil's cachaça and lime cocktail | U17: cachaça; sugar | W17: =COUNTA(N17:S17) -> 5 | X17: Yes | Y17: No | Z17: Yes | AB17: https://commons.wikimedia.org/w/index.php?search=Caipirinha+drink&title=Special:MediaSearch&type=image | AC17: https://thumb.wikimedia.org/wikipedia/commons/thumb/0/01/Caipirinha_with_lime.jpg/1280px-Caipirinha_with_lime.jpg | AD17: CC0 | AE17: rawpixel.com | AF17: Candidate - review | AG17: Draft v2 - editorial check
A18: B0017 | B18: Pisco Sour | D18: Peru | F18: Americas | G18: South America | H18: Cocktail | I18: Yes | J18: Coupe | K18: 2 | L18: 3 | M18: =INDEX('All Items'!$Q:$Q,MATCH($A18,'All Items'!$A:$A,0)) -> 7.15 | N18: lime | O18: angostura bitters | P18: egg white | Q18: frothy sour | R18: Peru | S18: pisco | T18: Peru's frothy brandy sour | U18: lime; angostura bitters; egg white; pisco | V18: frothy sour; pisco | W18: =COUNTA(N18:S18) -> 6 | X18: Yes | Y18: No | Z18: No | AA18: Peru and Chile both claim it | AB18: https://commons.wikimedia.org/w/index.php?search=Pisco+Sour+drink&title=Special:MediaSearch&type=image | AC18: https://thumb.wikimedia.org/wikipedia/commons/thumb/2/27/Pisco_sour_20100613b.JPG/1280px-Pisco_sour_20100613b.JPG | AD18: CC BY-SA 4.0 | AE18: Dtarazona | AF18: Candidate - review | AG18: Draft v2 - editorial check
A19: B0018 | B19: Espresso Martini | D19: United Kingdom | F19: Europe | G19: Northern Europe | H19: Cocktail | I19: Yes | J19: Martini glass | K19: 1 | L19: 4 | M19: =INDEX('All Items'!$Q:$Q,MATCH($A19,'All Items'!$A:$A,0)) -> 8.2 | N19: coffee liqueur | O19: vodka | P19: coffee cocktail | Q19: London | R19: fresh espresso | T19: A vodka and coffee cocktail | U19: coffee liqueur; vodka; fresh espresso | V19: fresh espresso | W19: =COUNTA(N19:S19) -> 5 | X19: Yes | Y19: No | Z19: Yes | AB19: https://commons.wikimedia.org/w/index.php?search=Espresso+Martini+drink&title=Special:MediaSearch&type=image | AC19: https://thumb.wikimedia.org/wikipedia/commons/thumb/5/55/Bistrot_Bruno_Loubet%2C_Clerkenwell%2C_London_%284574785649%29.jpg/1280px-Bistrot_Bruno_Loubet%2C_Clerkenwell%2C_London_%284574785649%29.jpg | AD19: CC BY-SA 2.0 | AE19: Ewan Munro from London, UK | AF19: Candidate - review | AG19: Draft v2 - editorial check
A20: B0019 | B20: Gin and Tonic | D20: United Kingdom | F20: Europe | G20: Northern Europe | H20: Cocktail | I20: Yes | J20: Highball or copa | K20: 1 | L20: 5 | M20: =INDEX('All Items'!$Q:$Q,MATCH($A20,'All Items'!$A:$A,0)) -> 9.75 | N20: lime | O20: juniper | P20: highball | Q20: British | R20: gin | S20: tonic water | T20: A juniper spirit topped with quinine mixer | U20: lime; juniper; gin; tonic water | V20: gin; tonic water | W20: =COUNTA(N20:S20) -> 6 | X20: Yes | Y20: No | Z20: Yes | AB20: https://commons.wikimedia.org/w/index.php?search=Gin+and+Tonic+drink&title=Special:MediaSearch&type=image | AF20: Needed | AG20: Draft v2 - editorial check
A21: B0020 | B21: Tom Collins | D21: United States | F21: Americas | G21: North America | H21: Cocktail | I21: Yes | J21: Collins glass | K21: 2 | L21: 3 | M21: =INDEX('All Items'!$Q:$Q,MATCH($A21,'All Items'!$A:$A,0)) -> 6.9 | N21: soda water | O21: lemon | P21: gin | Q21: tall gin fizz | R21: fizzy | T21: A tall, fizzy gin and lemon drink | U21: soda water; lemon; gin | W21: =COUNTA(N21:S21) -> 5 | X21: Yes | Y21: No | Z21: Yes | AB21: https://commons.wikimedia.org/w/index.php?search=Tom+Collins+drink&title=Special:MediaSearch&type=image | AF21: Needed | AG21: Draft v2 - editorial check
A22: B0021 | B22: Sex on the Beach | D22: United States | F22: Americas | G22: North America | H22: Cocktail | I22: Yes | J22: Highball | K22: 2 | L22: 3 | M22: =INDEX('All Items'!$Q:$Q,MATCH($A22,'All Items'!$A:$A,0)) -> 7.15 | N22: cranberry juice | O22: orange juice | P22: peach schnapps | Q22: vodka | R22: fruity vodka cocktail | T22: A fruity vodka cocktail with peach and cranberry | U22: cranberry juice; orange juice; peach schnapps; vodka | W22: =COUNTA(N22:S22) -> 5 | X22: Yes | Y22: No | Z22: Yes | AB22: https://commons.wikimedia.org/w/index.php?search=Sex+on+the+Beach+drink&title=Special:MediaSearch&type=image | AC22: https://thumb.wikimedia.org/wikipedia/commons/thumb/a/a2/Sex_On_The_Beach.jpg/1280px-Sex_On_The_Beach.jpg | AD22: CC BY 2.0 | AE22: Stuart Webster from Southampton, England | AF22: Candidate - review | AG22: Draft v2 - editorial check
A23: B0022 | B23: Tequila Sunrise | D23: United States | F23: Americas | G23: North America | H23: Cocktail | I23: Yes | J23: Highball | K23: 1 | L23: 4 | M23: =INDEX('All Items'!$Q:$Q,MATCH($A23,'All Items'!$A:$A,0)) -> 8.45 | N23: orange juice | O23: layered | P23: grenadine | Q23: sunset colours | R23: highball | S23: tequila | T23: An agave spirit with orange juice and sinking grenadine | U23: orange juice; grenadine; tequila | V23: tequila | W23: =COUNTA(N23:S23) -> 6 | X23: Yes | Y23: No | Z23: Yes | AB23: https://commons.wikimedia.org/w/index.php?search=Tequila+Sunrise+drink&title=Special:MediaSearch&type=image | AF23: Needed | AG23: Draft v2 - editorial check
A24: B0023 | B24: Bellini | D24: Italy | F24: Europe | G24: Southern Europe | H24: Cocktail | I24: Yes | J24: Flute | K24: 2 | L24: 3 | M24: =INDEX('All Items'!$Q:$Q,MATCH($A24,'All Items'!$A:$A,0)) -> 7.15 | N24: chilled | O24: prosecco | P24: white peach purée | Q24: peach and bubbles | R24: Venice | T24: Venice's peach and prosecco cocktail | U24: prosecco; white peach purée | W24: =COUNTA(N24:S24) -> 5 | X24: Yes | Y24: No | Z24: Yes | AB24: https://commons.wikimedia.org/w/index.php?search=Bellini+drink&title=Special:MediaSearch&type=image | AF24: Needed | AG24: Draft v2 - editorial check
A25: B0024 | B25: Mimosa | D25: France | F25: Europe | G25: Western Europe | H25: Cocktail | I25: Yes | J25: Flute | K25: 1 | L25: 4 | M25: =INDEX('All Items'!$Q:$Q,MATCH($A25,'All Items'!$A:$A,0)) -> 8.45 | N25: chilled | O25: brunch | P25: sparkling wine | Q25: orange juice | R25: brunch drink | S25: bubbles | T25: Sparkling wine with orange juice | U25: sparkling wine; orange juice | W25: =COUNTA(N25:S25) -> 6 | X25: Yes | Y25: No | Z25: Yes | AB25: https://commons.wikimedia.org/w/index.php?search=Mimosa+drink&title=Special:MediaSearch&type=image | AC25: https://thumb.wikimedia.org/wikipedia/commons/thumb/5/51/Mimosa_flowers_01.jpg/1280px-Mimosa_flowers_01.jpg | AD25: CC BY-SA 4.0 | AE25: This work was made by Nafiur Rahman and released under the license(s) stated below. Please feel free to use it for any purpose as long as you credit Nafiur Rahman as author and follow the terms of the chosen license. If you use this work outside of the Wikimedia projects, I would very much like to get a note from you. Thanks! | AF25: Candidate - review | AG25: Draft v2 - editorial check
A26: B0025 | B26: French 75 | D26: France | F26: Europe | G26: Western Europe | H26: Cocktail | I26: Yes | J26: Flute | K26: 2 | L26: 3 | M26: =INDEX('All Items'!$Q:$Q,MATCH($A26,'All Items'!$A:$A,0)) -> 6.9 | N26: lemon | O26: gin | P26: champagne | Q26: gin and bubbles | R26: flute | S26: World War I | T26: A gin, lemon and champagne cocktail | U26: lemon; gin; champagne | W26: =COUNTA(N26:S26) -> 6 | X26: Yes | Y26: No | Z26: Yes | AB26: https://commons.wikimedia.org/w/index.php?search=French+75+drink&title=Special:MediaSearch&type=image | AF26: Needed | AG26: Draft v2 - editorial check
A27: B0026 | B27: Sidecar | D27: France | F27: Europe | G27: Western Europe | H27: Cocktail | I27: Yes | J27: Coupe | K27: 2 | L27: 3 | M27: =INDEX('All Items'!$Q:$Q,MATCH($A27,'All Items'!$A:$A,0)) -> 7.15 | N27: lemon | O27: sugar rim | P27: triple sec | Q27: cognac | R27: brandy sour | S27: French | T27: A brandy, orange liqueur and lemon cocktail | U27: lemon; triple sec; cognac | W27: =COUNTA(N27:S27) -> 6 | X27: Yes | Y27: No | Z27: Yes | AB27: https://commons.wikimedia.org/w/index.php?search=Sidecar+drink&title=Special:MediaSearch&type=image | AF27: Needed | AG27: Draft v2 - editorial check
A28: B0027 | B28: Gimlet | D28: United Kingdom | F28: Europe | G28: Northern Europe | H28: Cocktail | I28: Yes | J28: Coupe | K28: 2 | L28: 3 | M28: =INDEX('All Items'!$Q:$Q,MATCH($A28,'All Items'!$A:$A,0)) -> 6.9 | N28: shaken | O28: lime cordial | P28: gin | Q28: gin sour | R28: British navy | T28: A gin and lime cordial cocktail | U28: lime cordial; gin | W28: =COUNTA(N28:S28) -> 5 | X28: Yes | Y28: No | Z28: Yes | AB28: https://commons.wikimedia.org/w/index.php?search=Gimlet+drink&title=Special:MediaSearch&type=image | AF28: Needed | AG28: Draft v2 - editorial check
