Workbook

Sheet README
A1: Foodle - starter content repository
A2: Prepared | B2: 15 October 2026
A3: Status | B3: Draft. Every row was hand-compiled and needs an editorial fact check (name, origin, ingredients) before it goes live.
A5: Record counts (live formulas)
A6: Dishes | B6: =COUNTA(Dishes!A:A)-1 -> 911
A7: of which puzzle ready | B7: =COUNTIF(Dishes!V:V,"Yes") -> 819
A8: India mode dishes | B8: =COUNTIF(Dishes!X:X,"Yes") -> 363
A9: Drinks | B9: =COUNTA(Drinks!A:A)-1 -> 247
A10: of which puzzle ready | B10: =COUNTIF(Drinks!W:W,"Yes") -> 129
A11: Ingredients | B11: =COUNTA(Ingredients!A:A)-1 -> 1484
A12: Cuisines (countries with items) | B12: =COUNTA(Cuisines!A:A)-1 -> 96
A13: India states / regions | B13: =COUNTA('India States'!A:A)-1 -> 29
A14: Country reference rows | B14: =COUNTA(Countries!A:A)-1 -> 250
A15: Total records | B15: =B6+B9+B11+B12+B13+B14 -> 3017
A17: How a clue row works
A18: Clue 1 ... Clue N | B18: Reveal order for the puzzle: least telling first, most telling last. A clue that names part of the answer is always moved to the end and listed under "Giveaway clues".
A19: Ingredients vs hints | B19: Clues are mostly ingredients. Some are hints (technique, vessel, look/taste, place, occasion, community/style); these are split out in "Non-ingredient hints".
A20: Fame (1-3) | B20: 1 = famous, 2 = well known, 3 = deep cut. Used to set daily difficulty.
A21: Puzzle ready | B21: Yes when the item has at least 5 clues and at least 3 ingredients. Items marked No stay in the repository as valid guesses (autocomplete) but are not served as answers.
A22: Global mode | B22: All non-Indian items plus Indian items with fame 1.
A23: India mode | B23: All Indian items, tagged by state.
A24: Country mode | B24: No when the origin is disputed or shared (see "Origin note"); those items are kept out of the guess-the-cuisine mode.
A25: Yellow cells | B25: Image URL, licence and credit are to be filled in during image sourcing. The Wikimedia link is a search, not a verified image.
A27: Sources and licences
A28: Dish and drink content | B28: Compiled by Claude from general knowledge for this draft. No third-party recipe database was copied. Facts must be checked against a reference (e.g. Wikipedia/Wikidata, national tourism boards, IBA for cocktails) before launch.
A29: Country reference sheet | B29: mledoze/countries (github.com/mledoze/countries), ODbL 1.0 licence: attribution required, share-alike applies to the country data.
A30: Images | B30: None included. See the concept note for the image sourcing plan.
A31: Daily Schedule (sample) | B31: First 90 days generated by a seeded random draw from puzzle-ready items, with difficulty by weekday (Mon/Tue/Sun easy, Wed/Thu/Sat medium, Fri hard) and no country (or, in state mode, state) repeated on consecutive days. The India dish and state-mode columns are drawn independently, so an item can appear in both. Dates are placeholders.

Sheet Dishes
A1: ID | B1: Dish | C1: Also known as | D1: Country | E1: State / region | F1: Continent | G1: Subregion | H1: Course | I1: Diet | J1: Fame (1-3) | K1: Clue 1 | L1: Clue 2 | M1: Clue 3 | N1: Clue 4 | O1: Clue 5 | P1: Clue 6 | Q1: Clue 7 | R1: Ingredients | S1: Non-ingredient hints | T1: Giveaway clues (shown last) | U1: Clue count | V1: Puzzle ready | W1: Global mode | X1: India mode | Y1: Country mode | Z1: Origin note | AA1: Image search (Wikimedia) | AB1: Image URL | AC1: Image licence | AD1: Image credit | AE1: Status
A2: D0001 | B2: Butter Chicken | C2: Murgh Makhani | D2: India | E2: Delhi | F2: Asia | G2: Southern Asia | H2: Main | I2: Non-veg | J2: 1 | K2: garlic | L2: ginger | M2: cream | N2: tomato | O2: chicken | P2: kasuri methi | Q2: butter | R2: garlic; ginger; cream; tomato; chicken; kasuri methi; butter | T2: butter | U2: 7 | V2: Yes | W2: Yes | X2: Yes | Y2: Yes | AA2: https://commons.wikimedia.org/w/index.php?search=Butter+Chicken+food&title=Special:MediaSearch&type=image | AE2: Draft - editorial check
A3: D0002 | B3: Chole Bhature | D3: India | E3: Punjab | F3: Asia | G3: Southern Asia | H3: Main | I3: Veg | J3: 1 | K3: onion | L3: tomato | M3: chana masala | N3: maida | O3: chickpeas | P3: bhatura dough | R3: onion; tomato; chana masala; maida; chickpeas; bhatura dough | U3: 6 | V3: Yes | W3: Yes | X3: Yes | Y3: Yes | AA3: https://commons.wikimedia.org/w/index.php?search=Chole+Bhature+food&title=Special:MediaSearch&type=image | AE3: Draft - editorial check
A4: D0003 | B4: Sarson da Saag | D4: India | E4: Punjab | F4: Asia | G4: Southern Asia | H4: Main | I4: Veg | J4: 1 | K4: garlic | L4: ginger | M4: green chilli | N4: spinach | O4: maize flour | P4: mustard greens | R4: garlic; ginger; green chilli; spinach; maize flour; mustard greens | U4: 6 | V4: Yes | W4: Yes | X4: Yes | Y4: Yes | AA4: https://commons.wikimedia.org/w/index.php?search=Sarson+da+Saag+food&title=Special:MediaSearch&type=image | AE4: Draft - editorial check
A5: D0004 | B5: Makki di Roti | D5: India | E5: Punjab | F5: Asia | G5: Southern Asia | H5: Bread | I5: Vegan | J5: 2 | K5: water | L5: salt | M5: ghee | N5: maize flour | R5: water; salt; ghee; maize flour | U5: 4 | V5: No | W5: No | X5: Yes | Y5: Yes | AA5: https://commons.wikimedia.org/w/index.php?search=Makki+di+Roti+food&title=Special:MediaSearch&type=image | AE5: Draft - editorial check
A6: D0005 | B6: Amritsari Kulcha | D6: India | E6: Punjab | F6: Asia | G6: Southern Asia | H6: Bread | I6: Veg | J6: 2 | K6: ajwain | L6: butter | M6: onion | N6: maida | O6: potato | P6: tandoor | R6: ajwain; butter; onion; maida; potato | S6: Vessel / serve: tandoor | U6: 6 | V6: Yes | W6: No | X6: Yes | Y6: Yes | AA6: https://commons.wikimedia.org/w/index.php?search=Amritsari+Kulcha+food&title=Special:MediaSearch&type=image | AE6: Draft - editorial check
A7: D0006 | B7: Dal Makhani | D7: India | E7: Punjab | F7: Asia | G7: Southern Asia | H7: Main | I7: Veg | J7: 1 | K7: garlic | L7: ginger | M7: tomato | N7: cream | O7: butter | P7: kidney beans | Q7: whole black urad dal | R7: garlic; ginger; tomato; cream; butter; kidney beans; whole black urad dal | U7: 7 | V7: Yes | W7: Yes | X7: Yes | Y7: Yes | AA7: https://commons.wikimedia.org/w/index.php?search=Dal+Makhani+food&title=Special:MediaSearch&type=image | AE7: Draft - editorial check
A8: D0007 | B8: Rajma Chawal | D8: India | E8: Punjab | F8: Asia | G8: Southern Asia | H8: Main | I8: Vegan | J8: 1 | K8: onion | L8: garlic | M8: ginger | N8: tomato | O8: rice | P8: kidney beans | R8: onion; garlic; ginger; tomato; rice; kidney beans | U8: 6 | V8: Yes | W8: Yes | X8: Yes | Y8: Yes | AA8: https://commons.wikimedia.org/w/index.php?search=Rajma+Chawal+food&title=Special:MediaSearch&type=image | AE8: Draft - editorial check
A9: D0008 | B9: Paneer Tikka | D9: India | E9: Punjab | F9: Asia | G9: Southern Asia | H9: Snack | I9: Veg | J9: 1 | K9: capsicum | L9: onion | M9: yogurt | N9: tandoori masala | O9: skewers | P9: paneer | R9: capsicum; onion; yogurt; tandoori masala; paneer | S9: Technique: skewers | U9: 6 | V9: Yes | W9: Yes | X9: Yes | Y9: Yes | AA9: https://commons.wikimedia.org/w/index.php?search=Paneer+Tikka+food&title=Special:MediaSearch&type=image | AE9: Draft - editorial check
A10: D0009 | B10: Tandoori Chicken | D10: India | E10: Punjab | F10: Asia | G10: Southern Asia | H10: Main | I10: Non-veg | J10: 1 | K10: lemon | L10: garlic | M10: ginger | N10: yogurt | O10: kashmiri chilli | P10: chicken | Q10: tandoor | R10: lemon; garlic; ginger; yogurt; kashmiri chilli; chicken | S10: Vessel / serve: tandoor | U10: 7 | V10: Yes | W10: Yes | X10: Yes | Y10: Yes | AA10: https://commons.wikimedia.org/w/index.php?search=Tandoori+Chicken+food&title=Special:MediaSearch&type=image | AE10: Draft - editorial check
A11: D0010 | B11: Amritsari Fish | D11: India | E11: Punjab | F11: Asia | G11: Southern Asia | H11: Snack | I11: Non-veg | J11: 2 | K11: lemon | L11: ajwain | M11: carom seeds | N11: gram flour | O11: red chilli | P11: fish | R11: lemon; ajwain; carom seeds; gram flour; red chilli; fish | U11: 6 | V11: Yes | W11: No | X11: Yes | Y11: Yes | AA11: https://commons.wikimedia.org/w/index.php?search=Amritsari+Fish+food&title=Special:MediaSearch&type=image | AE11: Draft - editorial check
A12: D0011 | B12: Pindi Chole | D12: India | E12: Punjab | F12: Asia | G12: Southern Asia | H12: Main | I12: Vegan | J12: 2 | K12: ginger | L12: green chilli | M12: pomegranate seed powder | N12: tea leaves | O12: chickpeas | R12: ginger; green chilli; pomegranate seed powder; tea leaves; chickpeas | U12: 5 | V12: Yes | W12: No | X12: Yes | Y12: Yes | AA12: https://commons.wikimedia.org/w/index.php?search=Pindi+Chole+food&title=Special:MediaSearch&type=image | AE12: Draft - editorial check
A13: D0012 | B13: Aloo Paratha | D13: India | E13: Punjab | F13: Asia | G13: Southern Asia | H13: Breakfast | I13: Veg | J13: 1 | K13: coriander | L13: green chilli | M13: ghee | N13: whole wheat flour | O13: potato | R13: coriander; green chilli; ghee; whole wheat flour; potato | U13: 5 | V13: Yes | W13: Yes | X13: Yes | Y13: Yes | AA13: https://commons.wikimedia.org/w/index.php?search=Aloo+Paratha+food&title=Special:MediaSearch&type=image | AE13: Draft - editorial check
A14: D0013 | B14: Gobi Paratha | D14: India | E14: Punjab | F14: Asia | G14: Southern Asia | H14: Breakfast | I14: Veg | J14: 2 | K14: coriander | L14: green chilli | M14: ghee | N14: whole wheat flour | O14: cauliflower | R14: coriander; green chilli; ghee; whole wheat flour; cauliflower | U14: 5 | V14: Yes | W14: No | X14: Yes | Y14: Yes | AA14: https://commons.wikimedia.org/w/index.php?search=Gobi+Paratha+food&title=Special:MediaSearch&type=image | AE14: Draft - editorial check
A15: D0014 | B15: Kadhi Pakora | D15: India | E15: Punjab | F15: Asia | G15: Southern Asia | H15: Main | I15: Veg | J15: 1 | K15: turmeric | L15: fenugreek seeds | M15: onion | N15: gram flour | O15: yogurt | P15: fritters | R15: turmeric; fenugreek seeds; onion; gram flour; yogurt; fritters | U15: 6 | V15: Yes | W15: Yes | X15: Yes | Y15: Yes | AA15: https://commons.wikimedia.org/w/index.php?search=Kadhi+Pakora+food&title=Special:MediaSearch&type=image | AE15: Draft - editorial check
A16: D0015 | B16: Pinni | D16: India | E16: Punjab | F16: Asia | G16: Southern Asia | H16: Sweet | I16: Veg | J16: 3 | K16: almond | L16: jaggery | M16: ghee | N16: whole wheat flour | O16: urad dal flour | R16: almond; jaggery; ghee; whole wheat flour; urad dal flour | U16: 5 | V16: Yes | W16: No | X16: Yes | Y16: Yes | AA16: https://commons.wikimedia.org/w/index.php?search=Pinni+food&title=Special:MediaSearch&type=image | AE16: Draft - editorial check
A17: D0016 | B17: Paneer Butter Masala | D17: India | E17: Delhi | F17: Asia | G17: Southern Asia | H17: Main | I17: Veg | J17: 1 | K17: cashew | L17: tomato | M17: cream | N17: kasuri methi | O17: paneer | P17: butter | R17: cashew; tomato; cream; kasuri methi; paneer; butter | T17: butter | U17: 6 | V17: Yes | W17: Yes | X17: Yes | Y17: Yes | AA17: https://commons.wikimedia.org/w/index.php?search=Paneer+Butter+Masala+food&title=Special:MediaSearch&type=image | AE17: Draft - editorial check
A18: D0017 | B18: Shahi Paneer | D18: India | E18: Delhi | F18: Asia | G18: Southern Asia | H18: Main | I18: Veg | J18: 1 | K18: cardamom | L18: onion | M18: cashew | N18: cream | O18: saffron | P18: paneer | R18: cardamom; onion; cashew; cream; saffron; paneer | U18: 6 | V18: Yes | W18: Yes | X18: Yes | Y18: Yes | AA18: https://commons.wikimedia.org/w/index.php?search=Shahi+Paneer+food&title=Special:MediaSearch&type=image | AE18: Draft - editorial check
A19: D0018 | B19: Kadai Paneer | D19: India | E19: Punjab | F19: Asia | G19: Southern Asia | H19: Main | I19: Veg | J19: 1 | K19: tomato | L19: onion | M19: coriander seed | N19: capsicum | O19: paneer | P19: kadai masala | R19: tomato; onion; coriander seed; capsicum; paneer; kadai masala | T19: kadai masala | U19: 6 | V19: Yes | W19: Yes | X19: Yes | Y19: Yes | AA19: https://commons.wikimedia.org/w/index.php?search=Kadai+Paneer+food&title=Special:MediaSearch&type=image | AE19: Draft - editorial check
A20: D0019 | B20: Malai Kofta | D20: India | E20: Delhi | F20: Asia | G20: Southern Asia | H20: Main | I20: Veg | J20: 1 | K20: cashew | L20: cream | M20: tomato | N20: potato | O20: raisins | P20: paneer dumplings | R20: cashew; cream; tomato; potato; raisins; paneer dumplings | U20: 6 | V20: Yes | W20: Yes | X20: Yes | Y20: Yes | AA20: https://commons.wikimedia.org/w/index.php?search=Malai+Kofta+food&title=Special:MediaSearch&type=image | AE20: Draft - editorial check
A21: D0020 | B21: Chicken Tikka Masala | D21: India | E21: Punjab | F21: Asia | G21: Southern Asia | H21: Main | I21: Non-veg | J21: 1 | K21: garlic | L21: onion | M21: cream | N21: tomato | O21: yogurt | P21: grilled chicken | R21: garlic; onion; cream; tomato; yogurt; grilled chicken | U21: 6 | V21: Yes | W21: Yes | X21: Yes | Y21: No | Z21: Origin disputed between India and the UK (Glasgow) | AA21: https://commons.wikimedia.org/w/index.php?search=Chicken+Tikka+Masala+food&title=Special:MediaSearch&type=image | AE21: Draft - editorial check
A22: D0021 | B22: Seekh Kebab | D22: India | E22: Delhi | F22: Asia | G22: Southern Asia | H22: Snack | I22: Non-veg | J22: 1 | K22: onion | L22: green chilli | M22: garam masala | N22: mint | O22: skewers | P22: minced mutton | R22: onion; green chilli; garam masala; mint; minced mutton | S22: Technique: skewers | U22: 6 | V22: Yes | W22: Yes | X22: Yes | Y22: Yes | AA22: https://commons.wikimedia.org/w/index.php?search=Seekh+Kebab+food&title=Special:MediaSearch&type=image | AE22: Draft - editorial check
A23: D0022 | B23: Nihari | D23: India | E23: Delhi | F23: Asia | G23: Southern Asia | H23: Main | I23: Non-veg | J23: 1 | K23: ginger | L23: fennel | M23: wheat flour | N23: bone marrow | O23: slow-cooked beef shank | P23: nihari masala | R23: ginger; fennel; wheat flour; bone marrow; slow-cooked beef shank; nihari masala | T23: nihari masala | U23: 6 | V23: Yes | W23: Yes | X23: Yes | Y23: Yes | AA23: https://commons.wikimedia.org/w/index.php?search=Nihari+food&title=Special:MediaSearch&type=image | AE23: Draft - editorial check
A24: D0023 | B24: Chicken Changezi | D24: India | E24: Delhi | F24: Asia | G24: Southern Asia | H24: Main | I24: Non-veg | J24: 3 | K24: cashew | L24: cream | M24: tomato | N24: onion | O24: egg | P24: chicken | R24: cashew; cream; tomato; onion; egg; chicken | U24: 6 | V24: Yes | W24: No | X24: Yes | Y24: Yes | AA24: https://commons.wikimedia.org/w/index.php?search=Chicken+Changezi+food&title=Special:MediaSearch&type=image | AE24: Draft - editorial check
A25: D0024 | B25: Aloo Tikki | D25: India | E25: Delhi | F25: Asia | G25: Southern Asia | H25: Street | I25: Veg | J25: 1 | K25: green chutney | L25: tamarind chutney | M25: breadcrumbs | N25: yogurt | O25: potato patty | R25: green chutney; tamarind chutney; breadcrumbs; yogurt; potato patty | U25: 5 | V25: Yes | W25: Yes | X25: Yes | Y25: Yes | AA25: https://commons.wikimedia.org/w/index.php?search=Aloo+Tikki+food&title=Special:MediaSearch&type=image | AE25: Draft - editorial check
A26: D0025 | B26: Papdi Chaat | D26: India | E26: Delhi | F26: Asia | G26: Southern Asia | H26: Street | I26: Veg | J26: 1 | K26: potato | L26: chickpeas | M26: tamarind chutney | N26: yogurt | O26: chaat masala | P26: papdi | R26: potato; chickpeas; tamarind chutney; yogurt; chaat masala; papdi | T26: chaat masala; papdi | U26: 6 | V26: Yes | W26: Yes | X26: Yes | Y26: Yes | AA26: https://commons.wikimedia.org/w/index.php?search=Papdi+Chaat+food&title=Special:MediaSearch&type=image | AE26: Draft - editorial check
A27: D0026 | B27: Dahi Bhalla | D27: India | E27: Delhi | F27: Asia | G27: Southern Asia | H27: Street | I27: Veg | J27: 1 | K27: roasted cumin | L27: tamarind chutney | M27: yogurt | N27: urad dal | O27: lentil dumplings | R27: roasted cumin; tamarind chutney; yogurt; urad dal; lentil dumplings | U27: 5 | V27: Yes | W27: Yes | X27: Yes | Y27: Yes | AA27: https://commons.wikimedia.org/w/index.php?search=Dahi+Bhalla+food&title=Special:MediaSearch&type=image | AE27: Draft - editorial check
A28: D0027 | B28: Ram Ladoo | D28: India | E28: Delhi | F28: Asia | G28: Southern Asia | H28: Street | I28: Vegan | J28: 3 | K28: lemon | L28: green chutney | M28: radish | N28: moong dal | O28: chana dal fritters | R28: lemon; green chutney; radish; moong dal; chana dal fritters | U28: 5 | V28: Yes | W28: No | X28: Yes | Y28: Yes | AA28: https://commons.wikimedia.org/w/index.php?search=Ram+Ladoo+food&title=Special:MediaSearch&type=image | AE28: Draft - editorial check
A29: D0028 | B29: Daulat ki Chaat | D29: India | E29: Delhi | F29: Asia | G29: Southern Asia | H29: Sweet | I29: Veg | J29: 3 | K29: pistachio | L29: saffron | M29: sugar | N29: winter dew | O29: milk froth | R29: pistachio; saffron; sugar; milk froth | S29: Look / taste: winter dew | U29: 5 | V29: Yes | W29: No | X29: Yes | Y29: Yes | AA29: https://commons.wikimedia.org/w/index.php?search=Daulat+ki+Chaat+food&title=Special:MediaSearch&type=image | AE29: Draft - editorial check
A30: D0029 | B30: Chole Kulche | D30: India | E30: Delhi | F30: Asia | G30: Southern Asia | H30: Street | I30: Vegan | J30: 2 | K30: onion | L30: lemon | M30: chickpeas | N30: tamarind | O30: kulcha | R30: onion; lemon; chickpeas; tamarind; kulcha | U30: 5 | V30: Yes | W30: No | X30: Yes | Y30: Yes | AA30: https://commons.wikimedia.org/w/index.php?search=Chole+Kulche+food&title=Special:MediaSearch&type=image | AE30: Draft - editorial check
A31: D0030 | B31: Parathe Wali Gali Paratha | D31: India | E31: Delhi | F31: Asia | G31: Southern Asia | H31: Breakfast | I31: Veg | J31: 3 | K31: potato | L31: paneer | M31: ghee | N31: deep fried | O31: whole wheat flour | R31: potato; paneer; ghee; whole wheat flour | S31: Technique: deep fried | U31: 5 | V31: Yes | W31: No | X31: Yes | Y31: Yes | AA31: https://commons.wikimedia.org/w/index.php?search=Parathe+Wali+Gali+Paratha+food&title=Special:MediaSearch&type=image | AE31: Draft - editorial check
A32: D0031 | B32: Jalebi | D32: India | E32: Delhi | F32: Asia | G32: Southern Asia | H32: Sweet | I32: Veg | J32: 1 | K32: saffron | L32: ghee | M32: maida | N32: sugar syrup | O32: spiral | R32: saffron; ghee; maida; sugar syrup | S32: Look / taste: spiral | U32: 5 | V32: Yes | W32: Yes | X32: Yes | Y32: No | Z32: West Asian origin, shared across South Asia | AA32: https://commons.wikimedia.org/w/index.php?search=Jalebi+food&title=Special:MediaSearch&type=image | AE32: Draft - editorial check
A33: D0032 | B33: Rabri | D33: India | E33: Uttar Pradesh | F33: Asia | G33: Southern Asia | H33: Sweet | I33: Veg | J33: 2 | K33: pistachio | L33: cardamom | M33: sugar | N33: saffron | O33: thickened milk layers | R33: pistachio; cardamom; sugar; saffron | S33: Look / taste: thickened milk layers | U33: 5 | V33: Yes | W33: No | X33: Yes | Y33: Yes | AA33: https://commons.wikimedia.org/w/index.php?search=Rabri+food&title=Special:MediaSearch&type=image | AE33: Draft - editorial check
A34: D0033 | B34: Kachori | D34: India | E34: Rajasthan | F34: Asia | G34: Southern Asia | H34: Snack | I34: Vegan | J34: 1 | K34: fennel | L34: asafoetida | M34: maida | N34: moong dal | O34: deep fried | R34: fennel; asafoetida; maida; moong dal | S34: Technique: deep fried | U34: 5 | V34: Yes | W34: Yes | X34: Yes | Y34: Yes | AA34: https://commons.wikimedia.org/w/index.php?search=Kachori+food&title=Special:MediaSearch&type=image | AE34: Draft - editorial check
A35: D0034 | B35: Lucknowi Biryani | C35: Awadhi Biryani | D35: India | E35: Uttar Pradesh | F35: Asia | G35: Southern Asia | H35: Rice | I35: Non-veg | J35: 1 | K35: kewra | L35: saffron | M35: ghee | N35: basmati rice | O35: mutton | P35: dum cooking | R35: kewra; saffron; ghee; basmati rice; mutton | S35: Technique: dum cooking | U35: 6 | V35: Yes | W35: Yes | X35: Yes | Y35: Yes | AA35: https://commons.wikimedia.org/w/index.php?search=Lucknowi+Biryani+food&title=Special:MediaSearch&type=image | AE35: Draft - editorial check
A36: D0035 | B36: Galouti Kebab | D36: India | E36: Uttar Pradesh | F36: Asia | G36: Southern Asia | H36: Snack | I36: Non-veg | J36: 1 | K36: saffron | L36: ghee | M36: rose water | N36: raw papaya | O36: minced mutton | P36: melt-in-mouth | R36: saffron; ghee; rose water; raw papaya; minced mutton | S36: Technique: melt-in-mouth | U36: 6 | V36: Yes | W36: Yes | X36: Yes | Y36: Yes | AA36: https://commons.wikimedia.org/w/index.php?search=Galouti+Kebab+food&title=Special:MediaSearch&type=image | AE36: Draft - editorial check
A37: D0036 | B37: Kakori Kebab | D37: India | E37: Uttar Pradesh | F37: Asia | G37: Southern Asia | H37: Snack | I37: Non-veg | J37: 2 | K37: cloves | L37: saffron | M37: kewra | N37: skewers | O37: minced mutton | R37: cloves; saffron; kewra; minced mutton | S37: Technique: skewers | U37: 5 | V37: Yes | W37: No | X37: Yes | Y37: Yes | AA37: https://commons.wikimedia.org/w/index.php?search=Kakori+Kebab+food&title=Special:MediaSearch&type=image | AE37: Draft - editorial check
A38: D0037 | B38: Tunday Kebab | D38: India | E38: Uttar Pradesh | F38: Asia | G38: Southern Asia | H38: Snack | I38: Non-veg | J38: 2 | K38: 160 spices | L38: ghee | M38: paratha | N38: minced buffalo meat | R38: ghee; paratha; minced buffalo meat | S38: Look / taste: 160 spices | U38: 4 | V38: No | W38: No | X38: Yes | Y38: Yes | AA38: https://commons.wikimedia.org/w/index.php?search=Tunday+Kebab+food&title=Special:MediaSearch&type=image | AE38: Draft - editorial check
A39: D0038 | B39: Korma | D39: India | E39: Uttar Pradesh | F39: Asia | G39: Southern Asia | H39: Main | I39: Non-veg | J39: 1 | K39: cardamom | L39: onion | M39: cashew | N39: yogurt | O39: mutton | P39: fried onion paste | R39: cardamom; onion; cashew; yogurt; mutton; fried onion paste | U39: 6 | V39: Yes | W39: Yes | X39: Yes | Y39: Yes | AA39: https://commons.wikimedia.org/w/index.php?search=Korma+food&title=Special:MediaSearch&type=image | AE39: Draft - editorial check
A40: D0039 | B40: Sheermal | D40: India | E40: Uttar Pradesh | F40: Asia | G40: Southern Asia | H40: Bread | I40: Veg | J40: 2 | K40: milk | L40: ghee | M40: sugar | N40: saffron | O40: maida | R40: milk; ghee; sugar; saffron; maida | U40: 5 | V40: Yes | W40: No | X40: Yes | Y40: Yes | AA40: https://commons.wikimedia.org/w/index.php?search=Sheermal+food&title=Special:MediaSearch&type=image | AE40: Draft - editorial check
...

Sheet Drinks
A1: ID | B1: Drink | C1: Also known as | D1: Country | E1: State / region | F1: Continent | G1: Subregion | H1: Type | I1: Alcoholic | J1: Fame (1-3) | K1: Clue 1 | L1: Clue 2 | M1: Clue 3 | N1: Clue 4 | O1: Clue 5 | P1: Clue 6 | Q1: Clue 7 | R1: Ingredients | S1: Non-ingredient hints | T1: Giveaway clues (shown last) | U1: Glass / serve | V1: Clue count | W1: Puzzle ready | X1: Global mode | Y1: India mode | Z1: Country mode | AA1: Origin note | AB1: Image search (Wikimedia) | AC1: Image URL | AD1: Image licence | AE1: Image credit | AF1: Status
A2: B0001 | B2: Mojito | D2: Cuba | F2: Americas | G2: Caribbean | H2: Cocktail | I2: Yes | J2: 1 | K2: ice | L2: soda water | M2: sugar | N2: lime | O2: white rum | P2: mint | R2: ice; soda water; sugar; lime; white rum; mint | U2: Highball | V2: 6 | W2: Yes | X2: Yes | Y2: No | Z2: Yes | AB2: https://commons.wikimedia.org/w/index.php?search=Mojito+drink&title=Special:MediaSearch&type=image | AF2: Draft - editorial check
A3: B0002 | B3: Margarita | D3: Mexico | F3: Americas | G3: North America | H3: Cocktail | I3: Yes | J3: 1 | K3: ice | L3: salt rim | M3: lime | N3: triple sec | O3: tequila | R3: ice; lime; triple sec; tequila | S3: Vessel / serve: salt rim | U3: Coupe or margarita glass | V3: 5 | W3: Yes | X3: Yes | Y3: No | Z3: Yes | AB3: https://commons.wikimedia.org/w/index.php?search=Margarita+drink&title=Special:MediaSearch&type=image | AF3: Draft - editorial check
A4: B0003 | B4: Piña Colada | D4: Puerto Rico | F4: Americas | G4: Caribbean | H4: Cocktail | I4: Yes | J4: 1 | K4: ice | L4: cream of coconut | M4: white rum | N4: blended | O4: pineapple juice | R4: ice; cream of coconut; white rum; pineapple juice | S4: Technique: blended | U4: Hurricane | V4: 5 | W4: Yes | X4: Yes | Y4: No | Z4: Yes | AB4: https://commons.wikimedia.org/w/index.php?search=Pi%C3%B1a+Colada+drink&title=Special:MediaSearch&type=image | AF4: Draft - editorial check
A5: B0004 | B5: Old Fashioned | D5: United States | F5: Americas | G5: North America | H5: Cocktail | I5: Yes | J5: 1 | K5: water | L5: sugar cube | M5: orange peel | N5: angostura bitters | O5: bourbon | R5: water; sugar cube; orange peel; angostura bitters; bourbon | U5: Rocks glass | V5: 5 | W5: Yes | X5: Yes | Y5: No | Z5: Yes | AB5: https://commons.wikimedia.org/w/index.php?search=Old+Fashioned+drink&title=Special:MediaSearch&type=image | AF5: Draft - editorial check
A6: B0005 | B6: Martini | D6: United States | F6: Americas | G6: North America | H6: Cocktail | I6: Yes | J6: 1 | K6: ice | L6: stirred | M6: olives | N6: dry vermouth | O6: gin | R6: ice; olives; dry vermouth; gin | S6: Technique: stirred | U6: Martini glass | V6: 5 | W6: Yes | X6: Yes | Y6: No | Z6: Yes | AB6: https://commons.wikimedia.org/w/index.php?search=Martini+drink&title=Special:MediaSearch&type=image | AF6: Draft - editorial check
A7: B0006 | B7: Negroni | D7: Italy | F7: Europe | G7: Southern Europe | H7: Cocktail | I7: Yes | J7: 1 | K7: ice | L7: orange peel | M7: sweet vermouth | N7: gin | O7: campari | R7: ice; orange peel; sweet vermouth; gin; campari | U7: Rocks glass | V7: 5 | W7: Yes | X7: Yes | Y7: No | Z7: Yes | AB7: https://commons.wikimedia.org/w/index.php?search=Negroni+drink&title=Special:MediaSearch&type=image | AF7: Draft - editorial check
A8: B0007 | B8: Cosmopolitan | D8: United States | F8: Americas | G8: North America | H8: Cocktail | I8: Yes | J8: 1 | K8: ice | L8: lime | M8: triple sec | N8: citrus vodka | O8: cranberry juice | R8: ice; lime; triple sec; citrus vodka; cranberry juice | U8: Martini glass | V8: 5 | W8: Yes | X8: Yes | Y8: No | Z8: Yes | AB8: https://commons.wikimedia.org/w/index.php?search=Cosmopolitan+drink&title=Special:MediaSearch&type=image | AF8: Draft - editorial check
A9: B0008 | B9: Daiquiri | D9: Cuba | F9: Americas | G9: Caribbean | H9: Cocktail | I9: Yes | J9: 1 | K9: ice | L9: sugar | M9: shaken | N9: lime | O9: white rum | R9: ice; sugar; lime; white rum | S9: Technique: shaken | U9: Coupe | V9: 5 | W9: Yes | X9: Yes | Y9: No | Z9: Yes | AB9: https://commons.wikimedia.org/w/index.php?search=Daiquiri+drink&title=Special:MediaSearch&type=image | AF9: Draft - editorial check
A10: B0009 | B10: Manhattan | D10: United States | F10: Americas | G10: North America | H10: Cocktail | I10: Yes | J10: 1 | K10: ice | L10: cherry | M10: angostura bitters | N10: sweet vermouth | O10: rye whiskey | R10: ice; cherry; angostura bitters; sweet vermouth; rye whiskey | U10: Coupe | V10: 5 | W10: Yes | X10: Yes | Y10: No | Z10: Yes | AB10: https://commons.wikimedia.org/w/index.php?search=Manhattan+drink&title=Special:MediaSearch&type=image | AF10: Draft - editorial check
A11: B0010 | B11: Bloody Mary | D11: France | F11: Europe | G11: Western Europe | H11: Cocktail | I11: Yes | J11: 1 | K11: celery | L11: black pepper | M11: Worcestershire sauce | N11: tabasco | O11: vodka | P11: tomato juice | R11: celery; black pepper; Worcestershire sauce; tabasco; vodka; tomato juice | U11: Highball | V11: 6 | W11: Yes | X11: Yes | Y11: No | Z11: No | AA11: Paris (Harry's New York Bar) and New York claims | AB11: https://commons.wikimedia.org/w/index.php?search=Bloody+Mary+drink&title=Special:MediaSearch&type=image | AF11: Draft - editorial check
A12: B0011 | B12: Moscow Mule | D12: United States | F12: Americas | G12: North America | H12: Cocktail | I12: Yes | J12: 1 | K12: ice | L12: lime | M12: ginger beer | N12: vodka | O12: copper mug | R12: ice; lime; ginger beer; vodka | S12: Vessel / serve: copper mug | U12: Copper mug | V12: 5 | W12: Yes | X12: Yes | Y12: No | Z12: Yes | AB12: https://commons.wikimedia.org/w/index.php?search=Moscow+Mule+drink&title=Special:MediaSearch&type=image | AF12: Draft - editorial check
A13: B0012 | B13: Whiskey Sour | D13: United States | F13: Americas | G13: North America | H13: Cocktail | I13: Yes | J13: 1 | K13: ice | L13: sugar | M13: egg white | N13: lemon | O13: whisky | R13: ice; sugar; egg white; lemon; whisky | U13: Rocks glass | V13: 5 | W13: Yes | X13: Yes | Y13: No | Z13: Yes | AB13: https://commons.wikimedia.org/w/index.php?search=Whiskey+Sour+drink&title=Special:MediaSearch&type=image | AF13: Draft - editorial check
A14: B0013 | B14: Mai Tai | D14: United States | F14: Americas | G14: North America | H14: Cocktail | I14: Yes | J14: 2 | K14: ice | L14: orgeat | M14: orange curaçao | N14: lime | O14: dark rum | R14: ice; orgeat; orange curaçao; lime; dark rum | U14: Rocks glass | V14: 5 | W14: Yes | X14: Yes | Y14: No | Z14: Yes | AB14: https://commons.wikimedia.org/w/index.php?search=Mai+Tai+drink&title=Special:MediaSearch&type=image | AF14: Draft - editorial check
A15: B0014 | B15: Long Island Iced Tea | D15: United States | F15: Americas | G15: North America | H15: Cocktail | I15: Yes | J15: 1 | K15: lemon | L15: vodka | M15: rum | N15: tequila | O15: gin | P15: cola | R15: lemon; vodka; rum; tequila; gin; cola | U15: Highball | V15: 6 | W15: Yes | X15: Yes | Y15: No | Z15: Yes | AB15: https://commons.wikimedia.org/w/index.php?search=Long+Island+Iced+Tea+drink&title=Special:MediaSearch&type=image | AF15: Draft - editorial check
A16: B0015 | B16: Aperol Spritz | D16: Italy | F16: Europe | G16: Southern Europe | H16: Cocktail | I16: Yes | J16: 1 | K16: ice | L16: orange slice | M16: soda water | N16: prosecco | O16: aperol | R16: ice; orange slice; soda water; prosecco; aperol | T16: aperol | U16: Wine glass | V16: 5 | W16: Yes | X16: Yes | Y16: No | Z16: Yes | AB16: https://commons.wikimedia.org/w/index.php?search=Aperol+Spritz+drink&title=Special:MediaSearch&type=image | AF16: Draft - editorial check
A17: B0016 | B17: Caipirinha | D17: Brazil | F17: Americas | G17: South America | H17: Cocktail | I17: Yes | J17: 1 | K17: ice | L17: sugar | M17: muddled lime | N17: cachaça | R17: ice; sugar; cachaça | S17: Technique: muddled lime | U17: Rocks glass | V17: 4 | W17: No | X17: Yes | Y17: No | Z17: Yes | AB17: https://commons.wikimedia.org/w/index.php?search=Caipirinha+drink&title=Special:MediaSearch&type=image | AF17: Draft - editorial check
A18: B0017 | B18: Pisco Sour | D18: Peru | F18: Americas | G18: South America | H18: Cocktail | I18: Yes | J18: 2 | K18: ice | L18: sugar | M18: angostura bitters | N18: egg white | O18: lime | P18: pisco | R18: ice; sugar; angostura bitters; egg white; lime; pisco | T18: pisco | U18: Coupe | V18: 6 | W18: Yes | X18: Yes | Y18: No | Z18: No | AA18: Peru and Chile both claim it | AB18: https://commons.wikimedia.org/w/index.php?search=Pisco+Sour+drink&title=Special:MediaSearch&type=image | AF18: Draft - editorial check
A19: B0018 | B19: Espresso Martini | D19: United Kingdom | F19: Europe | G19: Northern Europe | H19: Cocktail | I19: Yes | J19: 1 | K19: ice | L19: sugar | M19: coffee liqueur | N19: vodka | O19: fresh espresso | R19: ice; sugar; coffee liqueur; vodka; fresh espresso | T19: fresh espresso | U19: Martini glass | V19: 5 | W19: Yes | X19: Yes | Y19: No | Z19: Yes | AB19: https://commons.wikimedia.org/w/index.php?search=Espresso+Martini+drink&title=Special:MediaSearch&type=image | AF19: Draft - editorial check
A20: B0019 | B20: Gin and Tonic | D20: United Kingdom | F20: Europe | G20: Northern Europe | H20: Cocktail | I20: Yes | J20: 1 | K20: ice | L20: lime | M20: juniper | N20: gin | O20: tonic water | R20: ice; lime; juniper; gin; tonic water | T20: tonic water | U20: Highball or copa | V20: 5 | W20: Yes | X20: Yes | Y20: No | Z20: Yes | AB20: https://commons.wikimedia.org/w/index.php?search=Gin+and+Tonic+drink&title=Special:MediaSearch&type=image | AF20: Draft - editorial check
A21: B0020 | B21: Tom Collins | D21: United States | F21: Americas | G21: North America | H21: Cocktail | I21: Yes | J21: 2 | K21: ice | L21: sugar | M21: soda water | N21: lemon | O21: gin | R21: ice; sugar; soda water; lemon; gin | U21: Collins glass | V21: 5 | W21: Yes | X21: Yes | Y21: No | Z21: Yes | AB21: https://commons.wikimedia.org/w/index.php?search=Tom+Collins+drink&title=Special:MediaSearch&type=image | AF21: Draft - editorial check
A22: B0021 | B22: Sex on the Beach | D22: United States | F22: Americas | G22: North America | H22: Cocktail | I22: Yes | J22: 2 | K22: ice | L22: cranberry juice | M22: orange juice | N22: peach schnapps | O22: vodka | R22: ice; cranberry juice; orange juice; peach schnapps; vodka | U22: Highball | V22: 5 | W22: Yes | X22: Yes | Y22: No | Z22: Yes | AB22: https://commons.wikimedia.org/w/index.php?search=Sex+on+the+Beach+drink&title=Special:MediaSearch&type=image | AF22: Draft - editorial check
A23: B0022 | B23: Tequila Sunrise | D23: United States | F23: Americas | G23: North America | H23: Cocktail | I23: Yes | J23: 1 | K23: ice | L23: orange juice | M23: layered | N23: grenadine | O23: tequila | R23: ice; orange juice; grenadine; tequila | S23: Technique: layered | T23: tequila | U23: Highball | V23: 5 | W23: Yes | X23: Yes | Y23: No | Z23: Yes | AB23: https://commons.wikimedia.org/w/index.php?search=Tequila+Sunrise+drink&title=Special:MediaSearch&type=image | AF23: Draft - editorial check
A24: B0023 | B24: Bellini | D24: Italy | F24: Europe | G24: Southern Europe | H24: Cocktail | I24: Yes | J24: 2 | K24: chilled | L24: prosecco | M24: white peach purée | N24: Venice | R24: prosecco; white peach purée | S24: Technique: chilled; Place: Venice | U24: Flute | V24: 4 | W24: No | X24: Yes | Y24: No | Z24: Yes | AB24: https://commons.wikimedia.org/w/index.php?search=Bellini+drink&title=Special:MediaSearch&type=image | AF24: Draft - editorial check
A25: B0024 | B25: Mimosa | D25: France | F25: Europe | G25: Western Europe | H25: Cocktail | I25: Yes | J25: 1 | K25: chilled | L25: brunch | M25: sparkling wine | N25: orange juice | R25: sparkling wine; orange juice | S25: Technique: chilled; Occasion: brunch | U25: Flute | V25: 4 | W25: No | X25: Yes | Y25: No | Z25: Yes | AB25: https://commons.wikimedia.org/w/index.php?search=Mimosa+drink&title=Special:MediaSearch&type=image | AF25: Draft - editorial check
A26: B0025 | B26: French 75 | D26: France | F26: Europe | G26: Western Europe | H26: Cocktail | I26: Yes | J26: 2 | K26: ice | L26: sugar | M26: lemon | N26: gin | O26: champagne | R26: ice; sugar; lemon; gin; champagne | U26: Flute | V26: 5 | W26: Yes | X26: Yes | Y26: No | Z26: Yes | AB26: https://commons.wikimedia.org/w/index.php?search=French+75+drink&title=Special:MediaSearch&type=image | AF26: Draft - editorial check
A27: B0026 | B27: Sidecar | D27: France | F27: Europe | G27: Western Europe | H27: Cocktail | I27: Yes | J27: 2 | K27: ice | L27: sugar rim | M27: lemon | N27: triple sec | O27: cognac | R27: ice; lemon; triple sec; cognac | S27: Vessel / serve: sugar rim | U27: Coupe | V27: 5 | W27: Yes | X27: Yes | Y27: No | Z27: Yes | AB27: https://commons.wikimedia.org/w/index.php?search=Sidecar+drink&title=Special:MediaSearch&type=image | AF27: Draft - editorial check
A28: B0027 | B28: Gimlet | D28: United Kingdom | F28: Europe | G28: Northern Europe | H28: Cocktail | I28: Yes | J28: 2 | K28: ice | L28: shaken | M28: lime cordial | N28: gin | R28: ice; lime cordial; gin | S28: Technique: shaken | U28: Coupe | V28: 4 | W28: No | X28: Yes | Y28: No | Z28: Yes | AB28: https://commons.wikimedia.org/w/index.php?search=Gimlet+drink&title=Special:MediaSearch&type=image | AF28: Draft - editorial check
A29: B0028 | B29: Dark 'n' Stormy | D29: Bermuda | F29: Americas | G29: North America | H29: Cocktail | I29: Yes | J29: 2 | K29: ice | L29: lime | M29: ginger beer | N29: dark rum | R29: ice; lime; ginger beer; dark rum | T29: dark rum | U29: Highball | V29: 4 | W29: No | X29: Yes | Y29: No | Z29: Yes | AB29: https://commons.wikimedia.org/w/index.php?search=Dark+%27n%27+Stormy+drink&title=Special:MediaSearch&type=image | AF29: Draft - editorial check
A30: B0029 | B30: Paloma | D30: Mexico | F30: Americas | G30: North America | H30: Cocktail | I30: Yes | J30: 2 | K30: ice | L30: salt | M30: lime | N30: grapefruit soda | O30: tequila | R30: ice; salt; lime; grapefruit soda; tequila | U30: Highball | V30: 5 | W30: Yes | X30: Yes | Y30: No | Z30: Yes | AB30: https://commons.wikimedia.org/w/index.php?search=Paloma+drink&title=Special:MediaSearch&type=image | AF30: Draft - editorial check
A31: B0030 | B31: White Russian | D31: Belgium | F31: Europe | G31: Western Europe | H31: Cocktail | I31: Yes | J31: 2 | K31: ice | L31: cream | M31: coffee liqueur | N31: vodka | R31: ice; cream; coffee liqueur; vodka | U31: Rocks glass | V31: 4 | W31: No | X31: Yes | Y31: No | Z31: Yes | AB31: https://commons.wikimedia.org/w/index.php?search=White+Russian+drink&title=Special:MediaSearch&type=image | AF31: Draft - editorial check
A32: B0031 | B32: Black Russian | D32: Belgium | F32: Europe | G32: Western Europe | H32: Cocktail | I32: Yes | J32: 3 | K32: ice | L32: stirred | M32: coffee liqueur | N32: vodka | R32: ice; coffee liqueur; vodka | S32: Technique: stirred | U32: Rocks glass | V32: 4 | W32: No | X32: Yes | Y32: No | Z32: Yes | AB32: https://commons.wikimedia.org/w/index.php?search=Black+Russian+drink&title=Special:MediaSearch&type=image | AF32: Draft - editorial check
A33: B0032 | B33: Irish Coffee | D33: Ireland | F33: Europe | G33: Northern Europe | H33: Cocktail | I33: Yes | J33: 2 | K33: brown sugar | L33: hot coffee | M33: cream float | N33: irish whiskey | R33: brown sugar; hot coffee; cream float; irish whiskey | T33: irish whiskey | U33: Irish coffee glass | V33: 4 | W33: No | X33: Yes | Y33: No | Z33: Yes | AB33: https://commons.wikimedia.org/w/index.php?search=Irish+Coffee+drink&title=Special:MediaSearch&type=image | AF33: Draft - editorial check
A34: B0033 | B34: Mint Julep | D34: United States | F34: Americas | G34: North America | H34: Cocktail | I34: Yes | J34: 2 | K34: crushed ice | L34: sugar | M34: bourbon | N34: silver cup | O34: mint | R34: crushed ice; sugar; bourbon; mint | S34: Vessel / serve: silver cup | T34: mint | U34: Julep cup | V34: 5 | W34: Yes | X34: Yes | Y34: No | Z34: Yes | AB34: https://commons.wikimedia.org/w/index.php?search=Mint+Julep+drink&title=Special:MediaSearch&type=image | AF34: Draft - editorial check
A35: B0034 | B35: Sazerac | D35: United States | F35: Americas | G35: North America | H35: Cocktail | I35: Yes | J35: 3 | K35: sugar cube | L35: lemon peel | M35: peychaud's bitters | N35: absinthe rinse | O35: rye whiskey | R35: sugar cube; lemon peel; peychaud's bitters; absinthe rinse; rye whiskey | U35: Rocks glass | V35: 5 | W35: Yes | X35: Yes | Y35: No | Z35: Yes | AB35: https://commons.wikimedia.org/w/index.php?search=Sazerac+drink&title=Special:MediaSearch&type=image | AF35: Draft - editorial check
A36: B0035 | B36: Boulevardier | D36: France | F36: Europe | G36: Western Europe | H36: Cocktail | I36: Yes | J36: 3 | K36: ice | L36: orange peel | M36: sweet vermouth | N36: campari | O36: bourbon | R36: ice; orange peel; sweet vermouth; campari; bourbon | U36: Rocks glass | V36: 5 | W36: Yes | X36: Yes | Y36: No | Z36: Yes | AB36: https://commons.wikimedia.org/w/index.php?search=Boulevardier+drink&title=Special:MediaSearch&type=image | AF36: Draft - editorial check
A37: B0036 | B37: Americano | D37: Italy | F37: Europe | G37: Southern Europe | H37: Cocktail | I37: Yes | J37: 3 | K37: ice | L37: orange slice | M37: soda water | N37: sweet vermouth | O37: campari | R37: ice; orange slice; soda water; sweet vermouth; campari | U37: Highball | V37: 5 | W37: Yes | X37: Yes | Y37: No | Z37: Yes | AB37: https://commons.wikimedia.org/w/index.php?search=Americano+drink&title=Special:MediaSearch&type=image | AF37: Draft - editorial check
A38: B0037 | B38: Hurricane | D38: United States | F38: Americas | G38: North America | H38: Cocktail | I38: Yes | J38: 3 | K38: ice | L38: lime | M38: grenadine | N38: passion fruit | O38: dark rum | P38: New Orleans | R38: ice; lime; grenadine; passion fruit; dark rum | S38: Place: New Orleans | U38: Hurricane glass | V38: 6 | W38: Yes | X38: Yes | Y38: No | Z38: Yes | AB38: https://commons.wikimedia.org/w/index.php?search=Hurricane+drink&title=Special:MediaSearch&type=image | AF38: Draft - editorial check
A39: B0038 | B39: Zombie | D39: United States | F39: Americas | G39: North America | H39: Cocktail | I39: Yes | J39: 3 | K39: cinnamon syrup | L39: grenadine | M39: falernum | N39: lime | O39: absinthe | P39: multiple rums | R39: cinnamon syrup; grenadine; falernum; lime; absinthe | S39: Look / taste: multiple rums | U39: Tiki mug | V39: 6 | W39: Yes | X39: Yes | Y39: No | Z39: Yes | AB39: https://commons.wikimedia.org/w/index.php?search=Zombie+drink&title=Special:MediaSearch&type=image | AF39: Draft - editorial check
A40: B0039 | B40: Blue Lagoon | D40: France | F40: Europe | G40: Western Europe | H40: Cocktail | I40: Yes | J40: 2 | K40: ice | L40: lemonade | M40: vodka | N40: blue curaçao | R40: ice; lemonade; vodka; blue curaçao | T40: blue curaçao | U40: Highball | V40: 4 | W40: No | X40: Yes | Y40: No | Z40: Yes | AB40: https://commons.wikimedia.org/w/index.php?search=Blue+Lagoon+drink&title=Special:MediaSearch&type=image | AF40: Draft - editorial check
...

Sheet Ingredients
A1: ID | B1: Ingredient | C1: Category | D1: Used in dishes | E1: Used in drinks | F1: Total uses | G1: Example items | H1: Top countries | I1: Image search (Wikimedia) | J1: Image URL | K1: Image licence | L1: Status
A2: I0001 | B2: absinthe | C2: Alcohol | D2: 0 | E2: 1 | F2: =D2+E2 -> 1 | G2: Zombie | H2: United States | I2: https://commons.wikimedia.org/w/index.php?search=absinthe+ingredient&title=Special:MediaSearch&type=image | L2: Draft - editorial check
A3: I0002 | B3: absinthe rinse | C3: Alcohol | D3: 0 | E3: 2 | F3: =D3+E3 -> 2 | G3: Sazerac, Corpse Reviver No. 2 | H3: United States, United Kingdom | I3: https://commons.wikimedia.org/w/index.php?search=absinthe+rinse+ingredient&title=Special:MediaSearch&type=image | L3: Draft - editorial check
A4: I0003 | B4: achar | C4: Sauces, fats & condiments | D4: 1 | E4: 0 | F4: =D4+E4 -> 1 | G4: Dal Bhat | H4: Nepal | I4: https://commons.wikimedia.org/w/index.php?search=achar+ingredient&title=Special:MediaSearch&type=image | L4: Draft - editorial check
A5: I0004 | B5: achiote | C5: Herbs, spices & aromatics | D5: 2 | E5: 0 | F5: =D5+E5 -> 2 | G5: Tacos al Pastor, Cochinita Pibil | H5: Mexico | I5: https://commons.wikimedia.org/w/index.php?search=achiote+ingredient&title=Special:MediaSearch&type=image | L5: Draft - editorial check
A6: I0005 | B6: ackee | C6: Fruit & nuts | D6: 1 | E6: 0 | F6: =D6+E6 -> 1 | G6: Ackee and Saltfish | H6: Jamaica | I6: https://commons.wikimedia.org/w/index.php?search=ackee+ingredient&title=Special:MediaSearch&type=image | L6: Draft - editorial check
A7: I0006 | B7: agave | C7: Leavening & other | D7: 0 | E7: 2 | F7: =D7+E7 -> 2 | G7: Tequila, Mezcal | H7: Mexico | I7: https://commons.wikimedia.org/w/index.php?search=agave+ingredient&title=Special:MediaSearch&type=image | L7: Draft - editorial check
A8: I0007 | B8: aioli | C8: Dairy & egg | D8: 1 | E8: 0 | F8: =D8+E8 -> 1 | G8: Patatas Bravas | H8: Spain | I8: https://commons.wikimedia.org/w/index.php?search=aioli+ingredient&title=Special:MediaSearch&type=image | L8: Draft - editorial check
A9: I0008 | B9: ajitama egg | C9: Dairy & egg | D9: 1 | E9: 0 | F9: =D9+E9 -> 1 | G9: Tonkotsu Ramen | H9: Japan | I9: https://commons.wikimedia.org/w/index.php?search=ajitama+egg+ingredient&title=Special:MediaSearch&type=image | L9: Draft - editorial check
A10: I0009 | B10: ajwain | C10: Herbs, spices & aromatics | D10: 9 | E10: 0 | F10: =D10+E10 -> 9 | G10: Amritsari Kulcha, Amritsari Fish, Gatte ki Sabzi, Fafda Jalebi, Kanda Bhaji | H10: India | I10: https://commons.wikimedia.org/w/index.php?search=ajwain+ingredient&title=Special:MediaSearch&type=image | L10: Draft - editorial check
A11: I0010 | B11: ají amarillo | C11: Herbs, spices & aromatics | D11: 2 | E11: 0 | F11: =D11+E11 -> 2 | G11: Ají de Gallina, Causa Limeña | H11: Peru | I11: https://commons.wikimedia.org/w/index.php?search=aj%C3%AD+amarillo+ingredient&title=Special:MediaSearch&type=image | L11: Draft - editorial check
A12: I0011 | B12: ají panca | C12: Herbs, spices & aromatics | D12: 1 | E12: 0 | F12: =D12+E12 -> 1 | G12: Anticuchos | H12: Peru | I12: https://commons.wikimedia.org/w/index.php?search=aj%C3%AD+panca+ingredient&title=Special:MediaSearch&type=image | L12: Draft - editorial check
A13: I0012 | B13: alcohol | C13: Alcohol | D13: 0 | E13: 1 | F13: =D13+E13 -> 1 | G13: Limoncello | H13: Italy | I13: https://commons.wikimedia.org/w/index.php?search=alcohol+ingredient&title=Special:MediaSearch&type=image | L13: Draft - editorial check
... A1485: I1484 | B1485: zucchini | C1485: Vegetables & greens | D1485: 4 | E1485: 0 | F1485: =D1485+E1485 -> 4 | G1485: Jjajangmyeon, Doenjang Jjigae, Minestrone, Ratatouille | H1485: South Korea, Italy, France | I1485: https://commons.wikimedia.org/w/index.php?search=zucchini+ingredient&title=Special:MediaSearch&type=image | L1485: Draft - editorial check

Sheet Cuisines
A1: ID | B1: Country / cuisine | C1: Continent | D1: Subregion | E1: ISO2 | F1: Dishes | G1: Drinks | H1: Total items | I1: Signature dishes (fame 1) | J1: Most common ingredients
A2: C001 | B2: Afghanistan | C2: Asia | D2: Southern Asia | E2: AF | F2: =COUNTIF(Dishes!D:D,B2) -> 3 | G2: =COUNTIF(Drinks!D:D,B2) -> 0 | H2: =F2+G2 -> 3 | J2: cumin, almond, raisins, julienned carrot, lamb, rice, onion, split peas
A3: C002 | B3: Argentina | C3: Americas | D3: South America | E3: AR | F3: =COUNTIF(Dishes!D:D,B3) -> 6 | G3: =COUNTIF(Drinks!D:D,B3) -> 1 | H3: =F3+G3 -> 7 | I3: Asado, Empanadas | J3: chimichurri, chorizo, garlic, salt, beef ribs, olives, onion, boiled egg
A4: C003 | B4: Australia | C4: Oceania | D4: Australia and New Zealand | E4: AU | F4: =COUNTIF(Dishes!D:D,B4) -> 6 | G4: =COUNTIF(Drinks!D:D,B4) -> 1 | H4: =F4+G4 -> 7 | I4: Meat Pie | J4: butter, onion, gravy, tomato sauce, pastry, minced beef, sugar, chocolate coating
A5: C004 | B5: Austria | C5: Europe | D5: Central Europe | E5: AT | F5: =COUNTIF(Dishes!D:D,B5) -> 5 | G5: =COUNTIF(Drinks!D:D,B5) -> 0 | H5: =F5+G5 -> 5 | I5: Wiener Schnitzel | J5: lemon, breadcrumbs, raisins, butter, flour, egg, potato salad, veal cutlet
A6: C005 | B6: Bangladesh | C6: Asia | D6: Southern Asia | E6: BD | F6: =COUNTIF(Dishes!D:D,B6) -> 3 | G6: =COUNTIF(Drinks!D:D,B6) -> 0 | H6: =F6+G6 -> 3 | J6: yogurt, potato, kewra, saffron, mutton, green chilli, mustard paste, hilsa
A7: C006 | B7: Belgium | C7: Europe | D7: Western Europe | E7: BE | F7: =COUNTIF(Dishes!D:D,B7) -> 3 | G7: =COUNTIF(Drinks!D:D,B7) -> 4 | H7: =F7+G7 -> 7 | I7: Belgian Waffles | J7: yeast, cream, ice, coffee liqueur, vodka, celery, white wine, shallots
A8: C007 | B8: Bermuda | C8: Americas | D8: North America | E8: BM | F8: =COUNTIF(Dishes!D:D,B8) -> 0 | G8: =COUNTIF(Drinks!D:D,B8) -> 1 | H8: =F8+G8 -> 1 | J8: ice, lime, ginger beer, dark rum
A9: C008 | B9: Bhutan | C9: Asia | D9: Southern Asia | E9: BT | F9: =COUNTIF(Dishes!D:D,B9) -> 1 | G9: =COUNTIF(Drinks!D:D,B9) -> 0 | H9: =F9+G9 -> 1 | J9: onion, tomato, red rice, cheese, green chilli
A10: C009 | B10: Bolivia | C10: Americas | D10: South America | E10: BO | F10: =COUNTIF(Dishes!D:D,B10) -> 1 | G10: =COUNTIF(Drinks!D:D,B10) -> 0 | H10: =F10+G10 -> 1 | J10: potato, peas, juicy stew, baked pastry, beef
A11: C010 | B11: Bosnia and Herzegovina | C11: Europe | D11: Southeast Europe | E11: BA | F11: =COUNTIF(Dishes!D:D,B11) -> 2 | G11: =COUNTIF(Drinks!D:D,B11) -> 0 | H11: =F11+G11 -> 2 | J11: onion, kajmak, somun bread, garlic, grilled minced meat fingers, butter, filo pastry, minced beef
A12: C011 | B12: Brazil | C12: Americas | D12: South America | E12: BR | F12: =COUNTIF(Dishes!D:D,B12) -> 8 | G12: =COUNTIF(Drinks!D:D,B12) -> 4 | H12: =F12+G12 -> 12 | I12: Feijoada, Pão de Queijo, Brigadeiro | J12: sugar, farofa, dendê oil, ice, orange slice, collard greens, pork, sausage
A13: C012 | B13: Bulgaria | C13: Europe | D13: Southeast Europe | E13: BG | F13: =COUNTIF(Dishes!D:D,B13) -> 2 | G13: =COUNTIF(Drinks!D:D,B13) -> 0 | H13: =F13+G13 -> 2 | J13: butter, yogurt, egg, filo, white cheese, onion, capsicum, cucumber
A14: C013 | B14: Cambodia | C14: Asia | D14: South-Eastern Asia | E14: KH | F14: =COUNTIF(Dishes!D:D,B14) -> 2 | G14: =COUNTIF(Drinks!D:D,B14) -> 0 | H14: =F14+G14 -> 2 | J14: kroeung paste, noni leaf, coconut custard, fish, tomato, onion, lime pepper sauce, fried egg
A15: C014 | B15: Canada | C15: Americas | D15: North America | E15: CA | F15: =COUNTIF(Dishes!D:D,B15) -> 5 | G15: =COUNTIF(Drinks!D:D,B15) -> 2 | H15: =F15+G15 -> 7 | I15: Poutine | J15: pastry, salt, fries, squeaky cheese curds, brown gravy, egg, raisins, brown sugar filling
A16: C015 | B16: Cayman Islands | C16: Americas | D16: Caribbean | E16: KY | F16: =COUNTIF(Dishes!D:D,B16) -> 0 | G16: =COUNTIF(Drinks!D:D,B16) -> 1 | H16: =F16+G16 -> 1 | J16: ice, irish cream, coffee liqueur, vodka, chocolate
A17: C016 | B17: Chile | C17: Americas | D17: South America | E17: CL | F17: =COUNTIF(Dishes!D:D,B17) -> 1 | G17: =COUNTIF(Drinks!D:D,B17) -> 1 | H17: =F17+G17 -> 2 | J17: olives, raisins, boiled egg, minced beef, sweet corn topping, cinnamon, sugar, husked wheat
A18: C017 | B18: China | C18: Asia | D18: Eastern Asia | E18: CN | F18: =COUNTIF(Dishes!D:D,B18) -> 36 | G18: =COUNTIF(Drinks!D:D,B18) -> 7 | H18: =F18+G18 -> 43 | I18: Peking Duck, Kung Pao Chicken, Mapo Tofu, Xiaolongbao, Dim Sum Har Gow, Siu Mai | J18: soy sauce, spring onion, sichuan pepper, ginger, pork, shrimp, sugar, garlic
A19: C018 | B19: Colombia | C19: Americas | D19: South America | E19: CO | F19: =COUNTIF(Dishes!D:D,B19) -> 2 | G19: =COUNTIF(Drinks!D:D,B19) -> 0 | H19: =F19+G19 -> 2 | J19: avocado, arepa, fried egg, chorizo, chicharrón, red beans, capers, cream
A20: C019 | B20: Costa Rica | C20: Americas | D20: Central America | E20: CR | F20: =COUNTIF(Dishes!D:D,B20) -> 1 | G20: =COUNTIF(Drinks!D:D,B20) -> 0 | H20: =F20+G20 -> 1 | J20: onion, capsicum, coriander, salsa lizano, black beans, rice
A21: C020 | B21: Cuba | C21: Americas | D21: Caribbean | E21: CU | F21: =COUNTIF(Dishes!D:D,B21) -> 2 | G21: =COUNTIF(Drinks!D:D,B21) -> 4 | H21: =F21+G21 -> 6 | J21: ice, lime, sugar, white rum, soda water, mint, cumin, olives
A22: C021 | B22: Czechia | C22: Europe | D22: Central Europe | E22: CZ | F22: =COUNTIF(Dishes!D:D,B22) -> 2 | G22: =COUNTIF(Drinks!D:D,B22) -> 2 | H22: =F22+G22 -> 4 | J22: carrot, celeriac, cranberries, cream sauce, knedlíky, beef sirloin, butter, sugar
A23: C022 | B23: Denmark | C23: Europe | D23: Northern Europe | E23: DK | F23: =COUNTIF(Dishes!D:D,B23) -> 2 | G23: =COUNTIF(Drinks!D:D,B23) -> 0 | H23: =F23+G23 -> 2 | J23: butter, pickled herring, egg, rye bread, yeast, custard, fruit, laminated dough
A24: C023 | B24: Egypt | C24: Africa | D24: Northern Africa | E24: EG | F24: =COUNTIF(Dishes!D:D,B24) -> 5 | G24: =COUNTIF(Drinks!D:D,B24) -> 3 | H24: =F24+G24 -> 8 | I24: Falafel, Koshari | J24: garlic, cumin, rice, coconut, milk, sugar, ice, parsley
A25: C024 | B25: El Salvador | C25: Americas | D25: Central America | E25: SV | F25: =COUNTIF(Dishes!D:D,B25) -> 1 | G25: =COUNTIF(Drinks!D:D,B25) -> 0 | H25: =F25+G25 -> 1 | J25: beans, loroco, curtido, cheese, stuffed corn cakes
A26: C025 | B26: Ethiopia | C26: Africa | D26: Eastern Africa | E26: ET | F26: =COUNTIF(Dishes!D:D,B26) -> 3 | G26: =COUNTIF(Drinks!D:D,B26) -> 1 | H26: =F26+G26 -> 4 | I26: Injera with Doro Wat | J26: onion, niter kibbeh, berbere, boiled egg, chicken, sourdough flatbread, garlic, chickpea flour
A27: C026 | B27: Fiji | C27: Oceania | D27: Melanesia | E27: FJ | F27: =COUNTIF(Dishes!D:D,B27) -> 1 | G27: =COUNTIF(Drinks!D:D,B27) -> 0 | H27: =F27+G27 -> 1 | J27: tomato, onion, chilli, lime, coconut cream, raw fish
A28: C027 | B28: Finland | C28: Europe | D28: Northern Europe | E28: FI | F28: =COUNTIF(Dishes!D:D,B28) -> 1 | G28: =COUNTIF(Drinks!D:D,B28) -> 0 | H28: =F28+G28 -> 1 | J28: egg butter, milk, rice porridge, rye crust
A29: C028 | B29: France | C29: Europe | D29: Western Europe | E29: FR | F29: =COUNTIF(Dishes!D:D,B29) -> 31 | G29: =COUNTIF(Drinks!D:D,B29) -> 11 | H29: =F29+G29 -> 42 | I29: Croissant, Coq au Vin, Boeuf Bourguignon, Ratatouille, French Onion Soup, Crème Brûlée | J29: butter, sugar, cream, garlic, yeast, thyme, ice, milk
A30: C029 | B30: Georgia | C30: Asia | D30: Western Asia | E30: GE | F30: =COUNTIF(Dishes!D:D,B30) -> 2 | G30: =COUNTIF(Drinks!D:D,B30) -> 1 | H30: =F30+G30 -> 3 | I30: Khachapuri | J30: yeast dough, butter, sulguni, egg yolk, coriander, onion, black pepper, dumpling
A31: C030 | B31: Germany | C31: Europe | D31: Western Europe | E31: DE | F31: =COUNTIF(Dishes!D:D,B31) -> 12 | G31: =COUNTIF(Drinks!D:D,B31) -> 4 | H31: =F31+G31 -> 16 | I31: Bratwurst, Currywurst, Pretzel, Black Forest Cake | J31: mustard, cloves, flour, butter, caraway, yeast, egg, sugar
A32: C031 | B32: Ghana | C32: Africa | D32: Western Africa | E32: GH | F32: =COUNTIF(Dishes!D:D,B32) -> 3 | G32: =COUNTIF(Drinks!D:D,B32) -> 1 | H32: =F32+G32 -> 4 | J32: ginger, water, soup, plantain, cassava, cayenne, salt, spiced plantain
A33: C032 | B33: Greece | C33: Europe | D33: Southern Europe | E33: GR | F33: =COUNTIF(Dishes!D:D,B33) -> 11 | G33: =COUNTIF(Drinks!D:D,B33) -> 3 | H33: =F33+G33 -> 14 | I33: Moussaka, Greek Salad, Souvlaki, Gyros, Tzatziki | J33: tomato, lemon, cinnamon, oregano, dill, béchamel, onion, cucumber
A34: C033 | B34: Hungary | C34: Europe | D34: Central Europe | E34: HU | F34: =COUNTIF(Dishes!D:D,B34) -> 5 | G34: =COUNTIF(Drinks!D:D,B34) -> 2 | H34: =F34+G34 -> 7 | I34: Goulash | J34: onion, paprika, sour cream, yeast dough, butter, caraway, capsicum, potato
A35: C034 | B35: India | C35: Asia | D35: Southern Asia | E35: IN | F35: =COUNTIF(Dishes!D:D,B35) -> 363 | G35: =COUNTIF(Drinks!D:D,B35) -> 41 | H35: =F35+G35 -> 404 | I35: Butter Chicken, Chole Bhature, Sarson da Saag, Dal Makhani, Rajma Chawal, Paneer Tikka | J35: onion, cardamom, sugar, ghee, yogurt, green chilli, tomato, garlic
A36: C035 | B36: Indonesia | C36: Asia | D36: South-Eastern Asia | E36: ID | F36: =COUNTIF(Dishes!D:D,B36) -> 10 | G36: =COUNTIF(Drinks!D:D,B36) -> 1 | H36: =F36+G36 -> 11 | I36: Satay, Rendang, Nasi Goreng, Gado-Gado | J36: lemongrass, kecap manis, tofu, turmeric, peanut sauce, shallots, sambal, egg
A37: C036 | B37: International | C37: International | F37: =COUNTIF(Dishes!D:D,B37) -> 0 | G37: =COUNTIF(Drinks!D:D,B37) -> 3 | H37: =F37+G37 -> 3 | J37: water, molasses, sugarcane, potato, grain, yeast, honey
A38: C037 | B38: Iran | C38: Asia | D38: Southern Asia | E38: IR | F38: =COUNTIF(Dishes!D:D,B38) -> 6 | G38: =COUNTIF(Drinks!D:D,B38) -> 1 | H38: =F38+G38 -> 7 | J38: yogurt, kidney beans, herbs, onion, saffron, turmeric, loomi, lamb
A39: C038 | B39: Iraq | C39: Asia | D39: Western Asia | E39: IQ | F39: =COUNTIF(Dishes!D:D,B39) -> 2 | G39: =COUNTIF(Drinks!D:D,B39) -> 0 | H39: =F39+G39 -> 2 | J39: tomato, onion, tamarind, butterflied carp, rice, minced lamb, stuffed vegetables, vine leaves
A40: C039 | B40: Ireland | C40: Europe | D40: Northern Europe | E40: IE | F40: =COUNTIF(Dishes!D:D,B40) -> 3 | G40: =COUNTIF(Drinks!D:D,B40) -> 3 | H40: =F40+G40 -> 6 | J40: thyme, onion, carrot, potato, lamb, butter, milk, spring onion
...

Sheet India States
A1: State / region | B1: Dishes | C1: Drinks | D1: Total items | E1: Signature dishes (fame 1) | F1: Most common ingredients
A2: Andhra Pradesh | B2: =COUNTIFS(Dishes!E:E,A2,Dishes!D:D,"India") -> 11 | C2: =COUNTIFS(Drinks!E:E,A2,Drinks!D:D,"India") -> 0 | D2: =B2+C2 -> 11 | F2: tamarind, onion, garlic, red chilli, curry leaves, cumin, mustard seeds, sorrel leaves
A3: Arunachal Pradesh | B3: =COUNTIFS(Dishes!E:E,A3,Dishes!D:D,"India") -> 1 | C3: =COUNTIFS(Drinks!E:E,A3,Drinks!D:D,"India") -> 0 | D3: =B3+C3 -> 1 | F3: water, salt, millet flour
A4: Assam | B4: =COUNTIFS(Dishes!E:E,A4,Dishes!D:D,"India") -> 4 | C4: =COUNTIFS(Drinks!E:E,A4,Drinks!D:D,"India") -> 0 | D4: =B4+C4 -> 4 | F4: mustard oil, fenugreek, elephant apple, tomato, rohu, raw papaya, pulses, banana peel ash
A5: Bihar | B5: =COUNTIFS(Dishes!E:E,A5,Dishes!D:D,"India") -> 5 | C5: =COUNTIFS(Drinks!E:E,A5,Drinks!D:D,"India") -> 1 | D5: =B5+C5 -> 6 | E5: Litti Chokha | F5: mustard oil, garlic, aubergine, potato, roasted dough balls, sattu, fennel, coconut
A6: Chhattisgarh | B6: =COUNTIFS(Dishes!E:E,A6,Dishes!D:D,"India") -> 2 | C6: =COUNTIFS(Drinks!E:E,A6,Drinks!D:D,"India") -> 0 | D6: =B6+C6 -> 2 | F6: rice flour, onion, green chilli, coriander, pancake, sesame, rice, dumpling
A7: Delhi | B7: =COUNTIFS(Dishes!E:E,A7,Dishes!D:D,"India") -> 19 | C7: =COUNTIFS(Drinks!E:E,A7,Drinks!D:D,"India") -> 1 | D7: =B7+C7 -> 20 | E7: Butter Chicken, Paneer Butter Masala, Shahi Paneer, Malai Kofta, Seekh Kebab, Nihari | F7: cream, onion, tomato, cashew, tamarind chutney, yogurt, chicken, paneer
A8: Goa | B8: =COUNTIFS(Dishes!E:E,A8,Dishes!D:D,"India") -> 9 | C8: =COUNTIFS(Drinks!E:E,A8,Drinks!D:D,"India") -> 0 | D8: =B8+C8 -> 9 | E8: Goan Fish Curry, Pork Vindaloo | F8: vinegar, garlic, tamarind, red chilli, coconut milk, nutmeg, chicken, green chilli
A9: Gujarat | B9: =COUNTIFS(Dishes!E:E,A9,Dishes!D:D,"India") -> 18 | C9: =COUNTIFS(Drinks!E:E,A9,Drinks!D:D,"India") -> 0 | D9: =B9+C9 -> 18 | E9: Dhokla, Khandvi, Thepla, Undhiyu, Dabeli, Shrikhand | F9: sugar, yogurt, gram flour, cardamom, mustard seeds, sesame, whole wheat flour, jaggery
A10: Himachal Pradesh | B10: =COUNTIFS(Dishes!E:E,A10,Dishes!D:D,"India") -> 3 | C10: =COUNTIFS(Drinks!E:E,A10,Drinks!D:D,"India") -> 0 | D10: =B10+C10 -> 3 | F10: ghee, yogurt, yeast, poppy seeds, walnuts, steamed wheat bread, cardamom, gram flour
A11: Jammu & Kashmir | B11: =COUNTIFS(Dishes!E:E,A11,Dishes!D:D,"India") -> 7 | C11: =COUNTIFS(Drinks!E:E,A11,Drinks!D:D,"India") -> 2 | D11: =B11+C11 -> 9 | E11: Rogan Josh | F11: fennel, yogurt, cardamom, dry ginger, kashmiri chilli, mutton, pounded mutton balls, cinnamon
A12: Karnataka | B12: =COUNTIFS(Dishes!E:E,A12,Dishes!D:D,"India") -> 20 | C12: =COUNTIFS(Drinks!E:E,A12,Drinks!D:D,"India") -> 0 | D12: =B12+C12 -> 20 | E12: Masala Dosa, Mysore Pak, Bisi Bele Bath | F12: ghee, semolina, curry leaves, cardamom, sugar, coconut, tamarind, byadgi chilli
A13: Kerala | B13: =COUNTIFS(Dishes!E:E,A13,Dishes!D:D,"India") -> 22 | C13: =COUNTIFS(Drinks!E:E,A13,Drinks!D:D,"India") -> 0 | D13: =B13+C13 -> 22 | E13: Appam, Aviyal, Kerala Sadya, Puttu, Idiyappam, Kerala Fish Curry | F13: curry leaves, sugar, coconut oil, cardamom, coconut, rice, coconut milk, cashew
A14: Madhya Pradesh | B14: =COUNTIFS(Dishes!E:E,A14,Dishes!D:D,"India") -> 5 | C14: =COUNTIFS(Drinks!E:E,A14,Drinks!D:D,"India") -> 0 | D14: =B14+C14 -> 5 | F14: fennel, turmeric, pomegranate, sev, jeeravan, flattened rice, mustard seeds, green chilli
A15: Maharashtra | B15: =COUNTIFS(Dishes!E:E,A15,Dishes!D:D,"India") -> 30 | C15: =COUNTIFS(Drinks!E:E,A15,Drinks!D:D,"India") -> 1 | D15: =B15+C15 -> 31 | E15: Vada Pav, Pav Bhaji, Misal Pav, Poha, Sabudana Khichdi, Puran Poli | F15: onion, green chilli, jaggery, gram flour, pav, peanuts, cumin, potato
A16: Manipur | B16: =COUNTIFS(Dishes!E:E,A16,Dishes!D:D,"India") -> 2 | C16: =COUNTIFS(Drinks!E:E,A16,Drinks!D:D,"India") -> 0 | D16: =B16+C16 -> 2 | F16: potato, king chilli, fermented fish, mashed vegetables, cardamom, sugar, milk, black rice
A17: Meghalaya | B17: =COUNTIFS(Dishes!E:E,A17,Dishes!D:D,"India") -> 1 | C17: =COUNTIFS(Drinks!E:E,A17,Drinks!D:D,"India") -> 0 | D17: =B17+C17 -> 1 | F17: turmeric, onion, black pepper, pork, red rice
A18: Mizoram | B18: =COUNTIFS(Dishes!E:E,A18,Dishes!D:D,"India") -> 1 | C18: =COUNTIFS(Drinks!E:E,A18,Drinks!D:D,"India") -> 0 | D18: =B18+C18 -> 1 | F18: spinach, bamboo shoot, pork fat, vegetables
